<?xml version="1.0" encoding="utf-8"?>
<!-- =================================================================================== -->
<!-- |    This document was autogenerated by xacro from cricket_robot.urdf.xacro       | -->
<!-- |    EDITING THIS FILE BY HAND IS NOT RECOMMENDED                                 | -->
<!-- =================================================================================== -->
<robot name="cricket_robot">
  <material name="yellow">
    <color rgba="0.8 0.8 0 1"/>
  </material>
  <material name="red">
    <color rgba="1 0 0 1"/>
  </material>
  <!-- main body -->
  <link name="base_link">
    <visual>
      <geometry>
        <box size="0.41 0.36 0.06"/>
      </geometry>
      <material name="red"/>
    </visual>
    <collision>
      <geometry>
        <box size="0.41 0.36 0.06"/>
      </geometry>
    </collision>
  </link>
  <link name="dummy_link">
    <visual name="">
      <origin rpy="0.0 0.0 0.0" xyz="0.0 0.0 0.0"/>
      <geometry>
        <box size="0.41 0.36 0.06"/>
      </geometry>
      <material name="red"/>
    </visual>
    <collision>
      <origin rpy="0.0 0.0 0.0" xyz="0.0 0.0 0.0"/>
      <geometry>
        <box size="0.0 0.0 0.0"/>
      </geometry>
    </collision>
    <inertial>
      <mass value="10"/>
      <inertia ixx="1.0" ixy="0.0" ixz="0.0" iyy="1.0" iyz="0.0" izz="1.0"/>
    </inertial>
  </link>
  <joint name="dummy_joint" type="fixed">
    <origin rpy="0.0 0.0 0.0" xyz="0.0 0.0 0.0"/>
    <parent link="base_link"/>
    <child link="dummy_link"/>
    <axis xyz="0.0 0.0 0.0"/>
  </joint>
  <!-- ###################### -->
  <!-- #####  BODY  BOX ##### -->
  <!-- ###################### -->
  <link name="right_box">
    <visual>
      <geometry>
        <box size="0.1 0.04 0.06"/>
      </geometry>
      <material name="red"/>
    </visual>
    <collision>
      <geometry>
        <box size="0.1 0.04 0.06"/>
      </geometry>
    </collision>
  </link>
  <joint name="body_to_right_box" type="fixed">
    <parent link="base_link"/>
    <child link="right_box"/>
    <origin xyz="0.0 0.2 0.0"/>
  </joint>
  <link name="right_cylinder">
    <visual name="right_cylinder">
      <origin rpy="0 1.57075 0" xyz="0 0.0 0"/>
      <geometry>
        <cylinder length="0.1" radius="0.03"/>
      </geometry>
      <material name="red"/>
    </visual>
    <collision>
      <origin rpy="0 1.57075 0" xyz="0 0.0 0"/>
      <geometry>
        <cylinder length="0.1" radius="0.03"/>
      </geometry>
    </collision>
    <inertial>
      <mass value="0.5"/>
      <inertia ixx="1.0" ixy="0.0" ixz="0.0" iyy="1.0" iyz="0.0" izz="1.0"/>
    </inertial>
  </link>
  <joint name="right_box_to_cylinder" type="fixed">
    <parent link="right_box"/>
    <child link="right_cylinder"/>
    <origin rpy="0.0 0.0 0.0" xyz="0.0 0.02 0.0"/>
  </joint>
  <link name="left_box">
    <visual>
      <geometry>
        <box size="0.1 0.04 0.06"/>
      </geometry>
      <material name="red"/>
    </visual>
    <collision>
      <geometry>
        <box size="0.1 0.04 0.06"/>
      </geometry>
    </collision>
  </link>
  <joint name="body_to_left_box" type="fixed">
    <parent link="base_link"/>
    <child link="left_box"/>
    <origin xyz="0.0 -0.2 0.0"/>
  </joint>
  <link name="left_cylinder">
    <visual name="left_cylinder">
      <origin rpy="0 1.57075 0" xyz="0 0.0 0"/>
      <geometry>
        <cylinder length="0.1" radius="0.03"/>
      </geometry>
      <material name="red"/>
    </visual>
    <collision>
      <origin rpy="0 1.57075 0" xyz="0 0.0 0"/>
      <geometry>
        <cylinder length="0.1" radius="0.03"/>
      </geometry>
    </collision>
    <inertial>
      <mass value="0.5"/>
      <inertia ixx="1.0" ixy="0.0" ixz="0.0" iyy="1.0" iyz="0.0" izz="1.0"/>
    </inertial>
  </link>
  <joint name="left_box_to_cylinder" type="fixed">
    <parent link="left_box"/>
    <child link="left_cylinder"/>
    <origin rpy="0.0 0.0 0.0" xyz="0.0 -0.02 0.0"/>
  </joint>
  <!-- ###################### -->
  <!-- ##### RIGHT LEGS ##### -->
  <!-- ###################### -->
  <!-- SHOULDER 1 -->
  <link name="r_front_shoulder_cylinder">
    <visual name="r_front_shoulder_cylinder">
      <origin rpy="0 1.57075 0" xyz="0.0 0.0 0"/>
      <geometry>
        <cylinder length="0.12" radius="0.03"/>
      </geometry>
      <material name="yellow"/>
    </visual>
    <collision>
      <origin rpy="0 1.57075 0" xyz="0.0 0.0 0"/>
      <geometry>
        <cylinder length="0.12" radius="0.03"/>
      </geometry>
    </collision>
    <inertial>
      <mass value="0.5"/>
      <inertia ixx="1.0" ixy="0.0" ixz="0.0" iyy="1.0" iyz="0.0" izz="1.0"/>
    </inertial>
  </link>
  <joint name="r_front_shoulder_to_body" type="revolute">
    <axis xyz="1 0.0 0.0"/>
    <limit effort="1000.0" lower="-1.57075" upper="1.57075" velocity="0.5"/>
    <origin rpy="0 0 0.0" xyz="0.12 0.0 0.0"/>
    <parent link="right_cylinder"/>
    <child link="r_front_shoulder_cylinder"/>
    <limit effort="30" velocity="1.0"/>
    <dynamics damping="0.0" friction="0.0"/>
  </joint>
  <transmission name="r_front_shoulder_to_body_trans">
    <type>transmission_interface/SimpleTransmission</type>
    <actuator name="front_r_shoulder_to_body_motor">
      <mechanicalReduction>1</mechanicalReduction>
    </actuator>
    <joint name="r_front_shoulder_to_body">
      <hardwareInterface>hardware_interface/PositionJointInterface</hardwareInterface>
    </joint>
  </transmission>
  <link name="r_front_shoulder_box">
    <visual name="r_front_shoulder_box">
      <origin rpy="0 0 0" xyz="-0.05 -0.0005 0"/>
      <geometry>
        <box size="0.12 0.03 0.06"/>
      </geometry>
      <material name="yellow"/>
    </visual>
    <collision>
      <origin rpy="0 0 0" xyz="-0.05 -0.0005 0"/>
      <geometry>
        <box size="0.12 0.03 0.06"/>
      </geometry>
    </collision>
    <inertial>
      <mass value="3.5"/>
      <inertia ixx="1.0" ixy="0.0" ixz="0.0" iyy="1.0" iyz="0.0" izz="1.0"/>
    </inertial>
  </link>
  <joint name="r_front_shoulder_cyl_to_box" type="fixed">
    <origin rpy="0.0 0.0 0.0" xyz="0.05 0.017 0.0"/>
    <parent link="r_front_shoulder_cylinder"/>
    <child link="r_front_shoulder_box"/>
  </joint>
  <!-- SHOULDER 2 -->
  <link name="r_front_shoulder2_base">
    <visual name="r_front_shoulder2_base">
      <origin rpy="0.0 0.0 0.0" xyz="-0.015 0.0 0.0"/>
      <geometry>
        <box size="0.05 0.01 0.06"/>
      </geometry>
      <material name="yellow"/>
    </visual>
    <collision>
      <origin rpy="0.0 0.0 0.0" xyz="-0.015 0.0 0.0"/>
      <geometry>
        <box size="0.05 0.01 0.06"/>
      </geometry>
    </collision>
    <inertial>
      <mass value="0.5"/>
      <inertia ixx="1.0" ixy="0.0" ixz="0.0" iyy="1.0" iyz="0.0" izz="1.0"/>
    </inertial>
  </link>
  <joint name="r_front_shoulder2_to_shoulder" type="continuous">
    <axis xyz="0.0 1 0.0"/>
    <origin rpy="0.0 0.0 0.0" xyz="0.0 0.02 0.0"/>
    <parent link="r_front_shoulder_box"/>
    <child link="r_front_shoulder2_base"/>
    <limit effort="30" velocity="1.0"/>
    <dynamics damping="0.0" friction="0.0"/>
  </joint>
  <transmission name="r_front_shoulder2_to_shoulder_trans">
    <type>transmission_interface/SimpleTransmission</type>
    <actuator name="front_$_shoulder2_to_shoulder_motor">
      <mechanicalReduction>1</mechanicalReduction>
    </actuator>
    <joint name="r_front_shoulder2_to_shoulder">
      <hardwareInterface>hardware_interface/PositionJointInterface</hardwareInterface>
    </joint>
  </transmission>
  <link name="r_front_shoulder2_box">
    <visual name="r_front_shoulder2_box">
      <origin rpy="0.0 0.0 0.0" xyz="0.045 0.02 0.0"/>
      <geometry>
        <box size="0.11 0.05 0.06"/>
      </geometry>
      <material name="yellow"/>
    </visual>
    <collision>
      <origin rpy="0.0 0.0 0.0" xyz="0.045 0.02 0.0"/>
      <geometry>
        <box size="0.11 0.05 0.06"/>
      </geometry>
    </collision>
    <inertial>
      <mass value="3"/>
      <inertia ixx="1.0" ixy="0.0" ixz="0.0" iyy="1.0" iyz="0.0" izz="1.0"/>
    </inertial>
  </link>
  <joint name="r_front_shoulder2_base_to_box" type="fixed">
    <origin rpy="0.0 0.0 0.0" xyz="-0.14 0.0 0.0"/>
    <parent link="r_front_shoulder2_base"/>
    <child link="r_front_shoulder2_box"/>
  </joint>
  <!-- KNEE -->
  <link name="r_front_knee_base">
    <visual name="r_front_knee_base">
      <origin rpy="0.0 0.0 0.0" xyz="0.05 0.0 0.0"/>
      <geometry>
        <box size="0.12 0.01 0.06"/>
      </geometry>
      <material name="yellow"/>
    </visual>
    <collision>
      <origin rpy="0.0 0.0 0.0" xyz="0.05 0.0 0.0"/>
      <geometry>
        <box size="0.12 0.01 0.06"/>
      </geometry>
    </collision>
    <inertial>
      <mass value="0.5"/>
      <inertia ixx="1.0" ixy="0.0" ixz="0.0" iyy="1.0" iyz="0.0" izz="1.0"/>
    </inertial>
  </link>
  <joint name="r_front_shoulder2_to_knee" type="continuous">
    <axis xyz="0.0 1 0.0"/>
    <origin rpy="0.0 0.0 0.0" xyz="0.0 0.052 0.0"/>
    <parent link="r_front_shoulder2_box"/>
    <child link="r_front_knee_base"/>
    <limit effort="30" velocity="1.0"/>
    <dynamics damping="0.0" friction="0.0"/>
  </joint>
  <transmission name="r_front_shoulder2_to_knee_trans">
    <type>transmission_interface/SimpleTransmission</type>
    <actuator name="front_r_shoulder2_to_knee_motor">
      <mechanicalReduction>1</mechanicalReduction>
    </actuator>
    <joint name="r_front_shoulder2_to_knee">
      <hardwareInterface>hardware_interface/PositionJointInterface</hardwareInterface>
    </joint>
  </transmission>
  <link name="r_front_knee_box">
    <visual name="r_front_knee_box">
      <origin rpy="0.0 0.0 0.0" xyz="-0.03 -0.02 0.0"/>
      <geometry>
        <box size="0.08 0.05 0.06"/>
      </geometry>
      <material name="yellow"/>
    </visual>
    <collision>
      <origin rpy="0.0 0.0 0.0" xyz="-0.03 -0.02 0.0"/>
      <geometry>
        <box size="0.08 0.05 0.06"/>
      </geometry>
    </collision>
    <inertial>
      <mass value="3.5"/>
      <inertia ixx="1.0" ixy="0.0" ixz="0.0" iyy="1.0" iyz="0.0" izz="1.0"/>
    </inertial>
  </link>
  <joint name="r_front_knee_base_to_box" type="fixed">
    <origin rpy="0.0 0.0 0.0" xyz="0.18 0.0 0.0"/>
    <parent link="r_front_knee_base"/>
    <child link="r_front_knee_box"/>
  </joint>
  <!-- ANKLE & TRACK -->
  <link name="r_front_jointed_track">
    <visual name="r_front_jointed_track">
      <origin rpy="0.0 1.57075 1.57075" xyz="0.0 0.0 0.0"/>
      <geometry>
        <cylinder length="0.05" radius="0.03"/>
      </geometry>
      <material name="yellow"/>
    </visual>
    <collision>
      <origin rpy="0.0 1.57075 1.57075" xyz="0.0 0.0 0.0"/>
      <geometry>
        <cylinder length="0.05" radius="0.03"/>
      </geometry>
    </collision>
    <inertial>
      <mass value="0.5"/>
      <inertia ixx="1.0" ixy="0.0" ixz="0.0" iyy="1.0" iyz="0.0" izz="1.0"/>
    </inertial>
  </link>
  <joint name="r_front_ankle" type="continuous">
    <axis xyz="0.0 1 0.0"/>
    <origin rpy="0.0 0.0 0.0" xyz="0.0 0.032 0.0"/>
    <parent link="r_front_knee_box"/>
    <child link="r_front_jointed_track"/>
    <limit effort="30" velocity="1.0"/>
    <dynamics damping="0.0" friction="0.0"/>
  </joint>
  <transmission name="r_front_ankle_trans">
    <type>transmission_interface/SimpleTransmission</type>
    <actuator name="front_r_ankle_motor">
      <mechanicalReduction>1</mechanicalReduction>
    </actuator>
    <joint name="r_front_ankle">
      <hardwareInterface>hardware_interface/PositionJointInterface</hardwareInterface>
    </joint>
  </transmission>
  <link name="r_front_track">
    <visual name="r_front_track">
      <origin rpy="0.0 0.0 0.0" xyz="0.0 0.0 0.0"/>
      <geometry>
        <box size="0.190 0.05 0.06"/>
      </geometry>
      <material name="yellow"/>
    </visual>
    <collision>
      <origin rpy="0.0 0.0 0.0" xyz="0.0 0.0 0.0"/>
      <geometry>
        <box size="0.190 0.05 0.06"/>
      </geometry>
    </collision>
    <inertial>
      <mass value="4"/>
      <inertia ixx="1.0" ixy="0.0" ixz="0.0" iyy="1.0" iyz="0.0" izz="1.0"/>
    </inertial>
  </link>
  <joint name="r_front_jointed_track_to_track" type="fixed">
    <origin rpy="0.0 0.0 0.0" xyz="0.095 0.0 0.0"/>
    <parent link="r_front_jointed_track"/>
    <child link="r_front_track"/>
  </joint>
  <link name="r_front_ends_track">
    <visual name="r_front_ends_track">
      <origin rpy="0.0 1.57075 1.57075" xyz="0.0 0.0 0.0"/>
      <geometry>
        <cylinder length="0.05" radius="0.03"/>
      </geometry>
      <material name="yellow"/>
    </visual>
    <collision>
      <origin rpy="0.0 1.57075 1.57075" xyz="0.0 0.0 0.0"/>
      <geometry>
        <cylinder length="0.05" radius="0.03"/>
      </geometry>
    </collision>
    <inertial>
      <mass value="0.5"/>
      <inertia ixx="1.0" ixy="0.0" ixz="0.0" iyy="1.0" iyz="0.0" izz="1.0"/>
    </inertial>
  </link>
  <joint name="r_front_final_track_joint" type="continuous">
    <axis xyz="0.0 1 0.0"/>
    <origin rpy="0.0 0.0 0.0" xyz="0.095 0.0 0.0"/>
    <parent link="r_front_track"/>
    <child link="r_front_ends_track"/>
    <limit effort="30" velocity="1.0"/>
    <dynamics damping="0.0" friction="0.0"/>
  </joint>
  <transmission name="r_front_final_track_joint_trans">
    <type>transmission_interface/SimpleTransmission</type>
    <actuator name="front_r_final_track_joint_motor">
      <mechanicalReduction>1</mechanicalReduction>
    </actuator>
    <joint name="r_front_final_track_joint">
      <hardwareInterface>hardware_interface/VelocityJointInterface</hardwareInterface>
    </joint>
  </transmission>
  <gazebo reference="r_front_ends_track">
    <mu1 value="200.0"/>
    <mu2 value="100.0"/>
    <kp value="10000000.0"/>
    <kd value="1.0"/>
    <material>Gazebo/Grey</material>
  </gazebo>
  <!-- SHOULDER 1 -->
  <link name="r_back_shoulder_cylinder">
    <visual name="r_back_shoulder_cylinder">
      <origin rpy="0 1.57075 0" xyz="0.0 0.0 0"/>
      <geometry>
        <cylinder length="0.12" radius="0.03"/>
      </geometry>
      <material name="yellow"/>
    </visual>
    <collision>
      <origin rpy="0 1.57075 0" xyz="0.0 0.0 0"/>
      <geometry>
        <cylinder length="0.12" radius="0.03"/>
      </geometry>
    </collision>
    <inertial>
      <mass value="0.5"/>
      <inertia ixx="1.0" ixy="0.0" ixz="0.0" iyy="1.0" iyz="0.0" izz="1.0"/>
    </inertial>
  </link>
  <joint name="r_back_shoulder_to_body" type="revolute">
    <axis xyz="1 0.0 0.0"/>
    <limit effort="1000.0" lower="-1.57075" upper="1.57075" velocity="0.5"/>
    <origin rpy="0 0 0.0" xyz="-0.12 0.0 0.0"/>
    <parent link="right_cylinder"/>
    <child link="r_back_shoulder_cylinder"/>
    <limit effort="30" velocity="1.0"/>
    <dynamics damping="0.0" friction="0.0"/>
  </joint>
  <transmission name="r_back_shoulder_to_body_trans">
    <type>transmission_interface/SimpleTransmission</type>
    <actuator name="back_r_shoulder_to_body_motor">
      <mechanicalReduction>1</mechanicalReduction>
    </actuator>
    <joint name="r_back_shoulder_to_body">
      <hardwareInterface>hardware_interface/PositionJointInterface</hardwareInterface>
    </joint>
  </transmission>
  <link name="r_back_shoulder_box">
    <visual name="r_back_shoulder_box">
      <origin rpy="0 0 0" xyz="0.05 -0.0005 0"/>
      <geometry>
        <box size="0.12 0.03 0.06"/>
      </geometry>
      <material name="yellow"/>
    </visual>
    <collision>
      <origin rpy="0 0 0" xyz="0.05 -0.0005 0"/>
      <geometry>
        <box size="0.12 0.03 0.06"/>
      </geometry>
    </collision>
    <inertial>
      <mass value="3.5"/>
      <inertia ixx="1.0" ixy="0.0" ixz="0.0" iyy="1.0" iyz="0.0" izz="1.0"/>
    </inertial>
  </link>
  <joint name="r_back_shoulder_cyl_to_box" type="fixed">
    <origin rpy="0.0 0.0 0.0" xyz="-0.05 0.017 0.0"/>
    <parent link="r_back_shoulder_cylinder"/>
    <child link="r_back_shoulder_box"/>
  </joint>
  <!-- SHOULDER 2 -->
  <link name="r_back_shoulder2_base">
    <visual name="r_back_shoulder2_base">
      <origin rpy="0.0 0.0 0.0" xyz="0.015 0.0 0.0"/>
      <geometry>
        <box size="0.05 0.01 0.06"/>
      </geometry>
      <material name="yellow"/>
    </visual>
    <collision>
      <origin rpy="0.0 0.0 0.0" xyz="0.015 0.0 0.0"/>
      <geometry>
        <box size="0.05 0.01 0.06"/>
      </geometry>
    </collision>
    <inertial>
      <mass value="0.5"/>
      <inertia ixx="1.0" ixy="0.0" ixz="0.0" iyy="1.0" iyz="0.0" izz="1.0"/>
    </inertial>
  </link>
  <joint name="r_back_shoulder2_to_shoulder" type="continuous">
    <axis xyz="0.0 1 0.0"/>
    <origin rpy="0.0 0.0 0.0" xyz="0.0 0.02 0.0"/>
    <parent link="r_back_shoulder_box"/>
    <child link="r_back_shoulder2_base"/>
    <limit effort="30" velocity="1.0"/>
    <dynamics damping="0.0" friction="0.0"/>
  </joint>
  <transmission name="r_back_shoulder2_to_shoulder_trans">
    <type>transmission_interface/SimpleTransmission</type>
    <actuator name="back_$_shoulder2_to_shoulder_motor">
      <mechanicalReduction>1</mechanicalReduction>
    </actuator>
    <joint name="r_back_shoulder2_to_shoulder">
      <hardwareInterface>hardware_interface/PositionJointInterface</hardwareInterface>
    </joint>
  </transmission>
  <link name="r_back_shoulder2_box">
    <visual name="r_back_shoulder2_box">
      <origin rpy="0.0 0.0 0.0" xyz="-0.045 0.02 0.0"/>
      <geometry>
        <box size="0.11 0.05 0.06"/>
      </geometry>
      <material name="yellow"/>
    </visual>
    <collision>
      <origin rpy="0.0 0.0 0.0" xyz="-0.045 0.02 0.0"/>
      <geometry>
        <box size="0.11 0.05 0.06"/>
      </geometry>
    </collision>
    <inertial>
      <mass value="3"/>
      <inertia ixx="1.0" ixy="0.0" ixz="0.0" iyy="1.0" iyz="0.0" izz="1.0"/>
    </inertial>
  </link>
  <joint name="r_back_shoulder2_base_to_box" type="fixed">
    <origin rpy="0.0 0.0 0.0" xyz="0.14 0.0 0.0"/>
    <parent link="r_back_shoulder2_base"/>
    <child link="r_back_shoulder2_box"/>
  </joint>
  <!-- KNEE -->
  <link name="r_back_knee_base">
    <visual name="r_back_knee_base">
      <origin rpy="0.0 0.0 0.0" xyz="-0.05 0.0 0.0"/>
      <geometry>
        <box size="0.12 0.01 0.06"/>
      </geometry>
      <material name="yellow"/>
    </visual>
    <collision>
      <origin rpy="0.0 0.0 0.0" xyz="-0.05 0.0 0.0"/>
      <geometry>
        <box size="0.12 0.01 0.06"/>
      </geometry>
    </collision>
    <inertial>
      <mass value="0.5"/>
      <inertia ixx="1.0" ixy="0.0" ixz="0.0" iyy="1.0" iyz="0.0" izz="1.0"/>
    </inertial>
  </link>
  <joint name="r_back_shoulder2_to_knee" type="continuous">
    <axis xyz="0.0 1 0.0"/>
    <origin rpy="0.0 0.0 0.0" xyz="0.0 0.052 0.0"/>
    <parent link="r_back_shoulder2_box"/>
    <child link="r_back_knee_base"/>
    <limit effort="30" velocity="1.0"/>
    <dynamics damping="0.0" friction="0.0"/>
  </joint>
  <transmission name="r_back_shoulder2_to_knee_trans">
    <type>transmission_interface/SimpleTransmission</type>
    <actuator name="back_r_shoulder2_to_knee_motor">
      <mechanicalReduction>1</mechanicalReduction>
    </actuator>
    <joint name="r_back_shoulder2_to_knee">
      <hardwareInterface>hardware_interface/PositionJointInterface</hardwareInterface>
    </joint>
  </transmission>
  <link name="r_back_knee_box">
    <visual name="r_back_knee_box">
      <origin rpy="0.0 0.0 0.0" xyz="0.03 -0.02 0.0"/>
      <geometry>
        <box size="0.08 0.05 0.06"/>
      </geometry>
      <material name="yellow"/>
    </visual>
    <collision>
      <origin rpy="0.0 0.0 0.0" xyz="0.03 -0.02 0.0"/>
      <geometry>
        <box size="0.08 0.05 0.06"/>
      </geometry>
    </collision>
    <inertial>
      <mass value="3.5"/>
      <inertia ixx="1.0" ixy="0.0" ixz="0.0" iyy="1.0" iyz="0.0" izz="1.0"/>
    </inertial>
  </link>
  <joint name="r_back_knee_base_to_box" type="fixed">
    <origin rpy="0.0 0.0 0.0" xyz="-0.18 0.0 0.0"/>
    <parent link="r_back_knee_base"/>
    <child link="r_back_knee_box"/>
  </joint>
  <!-- ANKLE & TRACK -->
  <link name="r_back_jointed_track">
    <visual name="r_back_jointed_track">
      <origin rpy="0.0 1.57075 1.57075" xyz="0.0 0.0 0.0"/>
      <geometry>
        <cylinder length="0.05" radius="0.03"/>
      </geometry>
      <material name="yellow"/>
    </visual>
    <collision>
      <origin rpy="0.0 1.57075 1.57075" xyz="0.0 0.0 0.0"/>
      <geometry>
        <cylinder length="0.05" radius="0.03"/>
      </geometry>
    </collision>
    <inertial>
      <mass value="0.5"/>
      <inertia ixx="1.0" ixy="0.0" ixz="0.0" iyy="1.0" iyz="0.0" izz="1.0"/>
    </inertial>
  </link>
  <joint name="r_back_ankle" type="continuous">
    <axis xyz="0.0 1 0.0"/>
    <origin rpy="0.0 0.0 0.0" xyz="0.0 0.032 0.0"/>
    <parent link="r_back_knee_box"/>
    <child link="r_back_jointed_track"/>
    <limit effort="30" velocity="1.0"/>
    <dynamics damping="0.0" friction="0.0"/>
  </joint>
  <transmission name="r_back_ankle_trans">
    <type>transmission_interface/SimpleTransmission</type>
    <actuator name="back_r_ankle_motor">
      <mechanicalReduction>1</mechanicalReduction>
    </actuator>
    <joint name="r_back_ankle">
      <hardwareInterface>hardware_interface/PositionJointInterface</hardwareInterface>
    </joint>
  </transmission>
  <link name="r_back_track">
    <visual name="r_back_track">
      <origin rpy="0.0 0.0 0.0" xyz="0.0 0.0 0.0"/>
      <geometry>
        <box size="0.190 0.05 0.06"/>
      </geometry>
      <material name="yellow"/>
    </visual>
    <collision>
      <origin rpy="0.0 0.0 0.0" xyz="0.0 0.0 0.0"/>
      <geometry>
        <box size="0.190 0.05 0.06"/>
      </geometry>
    </collision>
    <inertial>
      <mass value="4"/>
      <inertia ixx="1.0" ixy="0.0" ixz="0.0" iyy="1.0" iyz="0.0" izz="1.0"/>
    </inertial>
  </link>
  <joint name="r_back_jointed_track_to_track" type="fixed">
    <origin rpy="0.0 3.1415 0.0" xyz="0.095 0.0 0.0"/>
    <parent link="r_back_jointed_track"/>
    <child link="r_back_track"/>
  </joint>
  <link name="r_back_ends_track">
    <visual name="r_back_ends_track">
      <origin rpy="0.0 1.57075 1.57075" xyz="0.0 0.0 0.0"/>
      <geometry>
        <cylinder length="0.05" radius="0.03"/>
      </geometry>
      <material name="yellow"/>
    </visual>
    <collision>
      <origin rpy="0.0 1.57075 1.57075" xyz="0.0 0.0 0.0"/>
      <geometry>
        <cylinder length="0.05" radius="0.03"/>
      </geometry>
    </collision>
    <inertial>
      <mass value="0.5"/>
      <inertia ixx="1.0" ixy="0.0" ixz="0.0" iyy="1.0" iyz="0.0" izz="1.0"/>
    </inertial>
  </link>
  <joint name="r_back_final_track_joint" type="continuous">
    <axis xyz="0.0 1 0.0"/>
    <origin rpy="0.0 0.0 0.0" xyz="-0.095 0.0 0.0"/>
    <parent link="r_back_track"/>
    <child link="r_back_ends_track"/>
    <limit effort="30" velocity="1.0"/>
    <dynamics damping="0.0" friction="0.0"/>
  </joint>
  <transmission name="r_back_final_track_joint_trans">
    <type>transmission_interface/SimpleTransmission</type>
    <actuator name="back_r_final_track_joint_motor">
      <mechanicalReduction>1</mechanicalReduction>
    </actuator>
    <joint name="r_back_final_track_joint">
      <hardwareInterface>hardware_interface/VelocityJointInterface</hardwareInterface>
    </joint>
  </transmission>
  <gazebo reference="r_back_ends_track">
    <mu1 value="200.0"/>
    <mu2 value="100.0"/>
    <kp value="10000000.0"/>
    <kd value="1.0"/>
    <material>Gazebo/Grey</material>
  </gazebo>
  <!-- ###################### -->
  <!-- ##### LEFT LEGS ###### -->
  <!-- ###################### -->
  <!-- SHOULDER 1 -->
  <link name="l_front_shoulder_cylinder">
    <visual name="l_front_shoulder_cylinder">
      <origin rpy="0 1.57075 0" xyz="0.0 0.0 0"/>
      <geometry>
        <cylinder length="0.12" radius="0.03"/>
      </geometry>
      <material name="yellow"/>
    </visual>
    <collision>
      <origin rpy="0 1.57075 0" xyz="0.0 0.0 0"/>
      <geometry>
        <cylinder length="0.12" radius="0.03"/>
      </geometry>
    </collision>
    <inertial>
      <mass value="3.5"/>
      <inertia ixx="1.0" ixy="0.0" ixz="0.0" iyy="1.0" iyz="0.0" izz="1.0"/>
    </inertial>
  </link>
  <joint name="l_front_shoulder_to_body" type="revolute">
    <axis xyz="1 0.0 0.0"/>
    <limit effort="1000.0" lower="-1.57075" upper="1.57075" velocity="0.5"/>
    <origin rpy="0 0 0.0" xyz="0.12 0.0 0.0"/>
    <parent link="left_cylinder"/>
    <child link="l_front_shoulder_cylinder"/>
    <limit effort="30" velocity="1.0"/>
  </joint>
  <transmission name="l_front_shoulder_to_body_trans">
    <type>transmission_interface/SimpleTransmission</type>
    <actuator name="front_l_shoulder_to_body_motor">
      <mechanicalReduction>1</mechanicalReduction>
    </actuator>
    <joint name="l_front_shoulder_to_body">
      <hardwareInterface>hardware_interface/PositionJointInterface</hardwareInterface>
    </joint>
  </transmission>
  <link name="l_front_shoulder_box">
    <visual name="l_front_shoulder_box">
      <origin rpy="0 0 0" xyz=" -0.05 0.0005 0"/>
      <geometry>
        <box size="0.12 0.03 0.06"/>
      </geometry>
      <material name="yellow"/>
    </visual>
    <collision>
      <origin rpy="0 0 0" xyz=" -0.05 0.0005 0"/>
      <geometry>
        <box size="0.12 0.03 0.06"/>
      </geometry>
    </collision>
    <inertial>
      <mass value="0.5"/>
      <inertia ixx="1.0" ixy="0.0" ixz="0.0" iyy="1.0" iyz="0.0" izz="1.0"/>
    </inertial>
  </link>
  <joint name="l_front_shoulder_cyl_to_box" type="fixed">
    <origin rpy="0.0 0.0 0.0" xyz="0.05 -0.017 0.0"/>
    <parent link="l_front_shoulder_cylinder"/>
    <child link="l_front_shoulder_box"/>
  </joint>
  <!-- SHOULDER 2  -->
  <link name="l_front_shoulder2_base">
    <visual name="l_front_shoulder2_base">
      <origin rpy="0.0 0.0 0.0" xyz="-0.015 0.0 0.0"/>
      <geometry>
        <box size="0.05 0.01 0.06"/>
      </geometry>
      <material name="yellow"/>
    </visual>
    <collision>
      <origin rpy="0.0 0.0 0.0" xyz="-0.015 0.0 0.0"/>
      <geometry>
        <box size="0.05 0.01 0.06"/>
      </geometry>
    </collision>
    <inertial>
      <mass value="0.5"/>
      <inertia ixx="1.0" ixy="0.0" ixz="0.0" iyy="1.0" iyz="0.0" izz="1.0"/>
    </inertial>
  </link>
  <joint name="l_front_shoulder2_to_shoulder" type="continuous">
    <axis xyz="0.0 1 0.0"/>
    <origin rpy="0.0 0.0 0.0" xyz="0.0 -0.02 0.0"/>
    <parent link="l_front_shoulder_box"/>
    <child link="l_front_shoulder2_base"/>
    <limit effort="30" velocity="1.0"/>
    <dynamics damping="0.0" friction="0.0"/>
  </joint>
  <transmission name="l_front_shoulder2_to_shoulder_trans">
    <type>transmission_interface/SimpleTransmission</type>
    <actuator name="front_l_shoulder2_to_shoulder_motor">
      <mechanicalReduction>1</mechanicalReduction>
    </actuator>
    <joint name="l_front_shoulder2_to_shoulder">
      <hardwareInterface>hardware_interface/PositionJointInterface</hardwareInterface>
    </joint>
  </transmission>
  <link name="l_front_shoulder2_box">
    <visual name="l_front_shoulder2_box">
      <origin rpy="0.0 0.0 0.0" xyz="0.045 -0.02 0.0"/>
      <geometry>
        <box size="0.11 0.05 0.06"/>
      </geometry>
      <material name="yellow"/>
    </visual>
    <collision>
      <origin rpy="0.0 0.0 0.0" xyz="0.045 -0.02 0.0"/>
      <geometry>
        <box size="0.11 0.05 0.06"/>
      </geometry>
    </collision>
    <inertial>
      <mass value="3"/>
      <inertia ixx="1.0" ixy="0.0" ixz="0.0" iyy="1.0" iyz="0.0" izz="1.0"/>
    </inertial>
  </link>
  <joint name="l_front_shoulder2_base_to_box" type="fixed">
    <origin rpy="0.0 0.0 0.0" xyz="-0.14 0.0 0.0"/>
    <parent link="l_front_shoulder2_base"/>
    <child link="l_front_shoulder2_box"/>
  </joint>
  <!-- KNEE -->
  <link name="l_front_knee_base">
    <visual name="l_front_knee_base">
      <origin rpy="0.0 0.0 0.0" xyz="0.05 0.0 0.0"/>
      <geometry>
        <box size="0.12 0.01 0.06"/>
      </geometry>
      <material name="yellow"/>
    </visual>
    <collision>
      <origin rpy="0.0 0.0 0.0" xyz="0.05 0.0 0.0"/>
      <geometry>
        <box size="0.12 0.01 0.06"/>
      </geometry>
    </collision>
    <inertial>
      <mass value="4"/>
      <inertia ixx="1.0" ixy="0.0" ixz="0.0" iyy="1.0" iyz="0.0" izz="1.0"/>
    </inertial>
  </link>
  <joint name="l_front_shoulder2_to_knee" type="continuous">
    <axis xyz="0.0 1 0.0"/>
    <origin rpy="0.0 0.0 0.0" xyz="0.0 -0.052 0.0"/>
    <parent link="l_front_shoulder2_box"/>
    <child link="l_front_knee_base"/>
  </joint>
  <transmission name="l_front_shoulder2_to_knee_trans">
    <type>transmission_interface/SimpleTransmission</type>
    <actuator name="front_l_shoulder2_to_knee_motor">
      <mechanicalReduction>1</mechanicalReduction>
    </actuator>
    <joint name="l_front_shoulder2_to_knee">
      <hardwareInterface>hardware_interface/PositionJointInterface</hardwareInterface>
    </joint>
  </transmission>
  <link name="l_front_knee_box">
    <visual name="l_front_knee_box">
      <origin rpy="0.0 0.0 0.0" xyz="-0.03 0.02 0.0"/>
      <geometry>
        <box size="0.08 0.05 0.06"/>
      </geometry>
      <material name="yellow"/>
    </visual>
    <collision>
      <origin rpy="0.0 0.0 0.0" xyz="-0.03 0.02 0.0"/>
      <geometry>
        <box size="0.08 0.05 0.06"/>
      </geometry>
    </collision>
    <inertial>
      <mass value="0.5"/>
      <inertia ixx="1.0" ixy="0.0" ixz="0.0" iyy="1.0" iyz="0.0" izz="1.0"/>
    </inertial>
  </link>
  <joint name="l_front_knee_base_to_box" type="fixed">
    <origin rpy="0.0 0.0 0.0" xyz="0.18 0.0 0.0"/>
    <parent link="l_front_knee_base"/>
    <child link="l_front_knee_box"/>
  </joint>
  <!-- ANKLE & TRACK -->
  <link name="l_front_jointed_track">
    <visual name="l_front_jointed_track">
      <origin rpy="0.0 1.57075 1.57075" xyz="0.0 0.0 0.0"/>
      <geometry>
        <cylinder length="0.05" radius="0.03"/>
      </geometry>
      <material name="yellow"/>
    </visual>
    <collision>
      <origin rpy="0.0 1.57075 1.57075" xyz="0.0 0.0 0.0"/>
      <geometry>
        <cylinder length="0.05" radius="0.03"/>
      </geometry>
    </collision>
    <inertial>
      <mass value="0.5"/>
      <inertia ixx="1.0" ixy="0.0" ixz="0.0" iyy="1.0" iyz="0.0" izz="1.0"/>
    </inertial>
  </link>
  <joint name="l_front_ankle" type="continuous">
    <axis xyz="0.0 1 0.0"/>
    <origin rpy="0.0 0.0 0.0" xyz="0.0 -0.032 0.0"/>
    <parent link="l_front_knee_box"/>
    <child link="l_front_jointed_track"/>
  </joint>
  <transmission name="l_front_ankle_trans">
    <type>transmission_interface/SimpleTransmission</type>
    <actuator name="front_l_ankle_motor">
      <mechanicalReduction>1</mechanicalReduction>
    </actuator>
    <joint name="l_front_ankle">
      <hardwareInterface>hardware_interface/PositionJointInterface</hardwareInterface>
    </joint>
  </transmission>
  <link name="l_front_track">
    <visual name="l_front_track">
      <origin rpy="0.0 0.0 0.0" xyz="0.0 0.0 0.0"/>
      <geometry>
        <box size="0.190 0.05 0.06"/>
      </geometry>
      <material name="yellow"/>
    </visual>
    <collision>
      <origin rpy="0.0 0.0 0.0" xyz="0.0 0.0 0.0"/>
      <geometry>
        <box size="0.190 0.05 0.06"/>
      </geometry>
    </collision>
    <inertial>
      <mass value="4.5"/>
      <inertia ixx="1.0" ixy="0.0" ixz="0.0" iyy="1.0" iyz="0.0" izz="1.0"/>
    </inertial>
  </link>
  <joint name="l_front_jointed_track_to_track" type="fixed">
    <origin rpy="0.0 0.0 0.0" xyz="0.095 0.0 0.0"/>
    <parent link="l_front_jointed_track"/>
    <child link="l_front_track"/>
  </joint>
  <link name="l_front_ends_track">
    <visual name="l_front_ends_track">
      <origin rpy="0.0 1.57075 1.57075" xyz="0.0 0.0 0.0"/>
      <geometry>
        <cylinder length="0.05" radius="0.03"/>
      </geometry>
      <material name="yellow"/>
    </visual>
    <collision>
      <origin rpy="0.0 1.57075 1.57075" xyz="0.0 0.0 0.0"/>
      <geometry>
        <cylinder length="0.05" radius="0.03"/>
      </geometry>
    </collision>
    <inertial>
      <mass value="0.5"/>
      <inertia ixx="1.0" ixy="0.0" ixz="0.0" iyy="1.0" iyz="0.0" izz="1.0"/>
    </inertial>
  </link>
  <joint name="l_front_final_track_joint" type="continuous">
    <axis xyz="0.0 1 0.0"/>
    <origin rpy="0.0 0.0 0.0" xyz="0.095 0.0 0.0"/>
    <parent link="l_front_track"/>
    <child link="l_front_ends_track"/>
  </joint>
  <transmission name="l_front_final_track_joint_trans">
    <type>transmission_interface/SimpleTransmission</type>
    <actuator name="front_l_final_track_joint_motor">
      <mechanicalReduction>1</mechanicalReduction>
    </actuator>
    <joint name="l_front_final_track_joint">
      <hardwareInterface>hardware_interface/VelocityJointInterface</hardwareInterface>
      <!-- <hardwareInterface>hardware_interface/PositionJointInterface</hardwareInterface> -->
    </joint>
  </transmission>
  <gazebo reference="r_front_ends_track">
    <mu1 value="200.0"/>
    <mu2 value="100.0"/>
    <kp value="10000000.0"/>
    <kd value="1.0"/>
    <material>Gazebo/Grey</material>
  </gazebo>
  <!-- SHOULDER 1 -->
  <link name="l_back_shoulder_cylinder">
    <visual name="l_back_shoulder_cylinder">
      <origin rpy="0 1.57075 0" xyz="0.0 0.0 0"/>
      <geometry>
        <cylinder length="0.12" radius="0.03"/>
      </geometry>
      <material name="yellow"/>
    </visual>
    <collision>
      <origin rpy="0 1.57075 0" xyz="0.0 0.0 0"/>
      <geometry>
        <cylinder length="0.12" radius="0.03"/>
      </geometry>
    </collision>
    <inertial>
      <mass value="3.5"/>
      <inertia ixx="1.0" ixy="0.0" ixz="0.0" iyy="1.0" iyz="0.0" izz="1.0"/>
    </inertial>
  </link>
  <joint name="l_back_shoulder_to_body" type="revolute">
    <axis xyz="1 0.0 0.0"/>
    <limit effort="1000.0" lower="-1.57075" upper="1.57075" velocity="0.5"/>
    <origin rpy="0 0 0.0" xyz="-0.12 0.0 0.0"/>
    <parent link="left_cylinder"/>
    <child link="l_back_shoulder_cylinder"/>
    <limit effort="30" velocity="1.0"/>
  </joint>
  <transmission name="l_back_shoulder_to_body_trans">
    <type>transmission_interface/SimpleTransmission</type>
    <actuator name="back_l_shoulder_to_body_motor">
      <mechanicalReduction>1</mechanicalReduction>
    </actuator>
    <joint name="l_back_shoulder_to_body">
      <hardwareInterface>hardware_interface/PositionJointInterface</hardwareInterface>
    </joint>
  </transmission>
  <link name="l_back_shoulder_box">
    <visual name="l_back_shoulder_box">
      <origin rpy="0 0 0" xyz=" 0.05 0.0005 0"/>
      <geometry>
        <box size="0.12 0.03 0.06"/>
      </geometry>
      <material name="yellow"/>
    </visual>
    <collision>
      <origin rpy="0 0 0" xyz=" 0.05 0.0005 0"/>
      <geometry>
        <box size="0.12 0.03 0.06"/>
      </geometry>
    </collision>
    <inertial>
      <mass value="0.5"/>
      <inertia ixx="1.0" ixy="0.0" ixz="0.0" iyy="1.0" iyz="0.0" izz="1.0"/>
    </inertial>
  </link>
  <joint name="l_back_shoulder_cyl_to_box" type="fixed">
    <origin rpy="0.0 0.0 0.0" xyz="-0.05 -0.017 0.0"/>
    <parent link="l_back_shoulder_cylinder"/>
    <child link="l_back_shoulder_box"/>
  </joint>
  <!-- SHOULDER 2  -->
  <link name="l_back_shoulder2_base">
    <visual name="l_back_shoulder2_base">
      <origin rpy="0.0 0.0 0.0" xyz="0.015 0.0 0.0"/>
      <geometry>
        <box size="0.05 0.01 0.06"/>
      </geometry>
      <material name="yellow"/>
    </visual>
    <collision>
      <origin rpy="0.0 0.0 0.0" xyz="0.015 0.0 0.0"/>
      <geometry>
        <box size="0.05 0.01 0.06"/>
      </geometry>
    </collision>
    <inertial>
      <mass value="0.5"/>
      <inertia ixx="1.0" ixy="0.0" ixz="0.0" iyy="1.0" iyz="0.0" izz="1.0"/>
    </inertial>
  </link>
  <joint name="l_back_shoulder2_to_shoulder" type="continuous">
    <axis xyz="0.0 1 0.0"/>
    <origin rpy="0.0 0.0 0.0" xyz="0.0 -0.02 0.0"/>
    <parent link="l_back_shoulder_box"/>
    <child link="l_back_shoulder2_base"/>
    <limit effort="30" velocity="1.0"/>
    <dynamics damping="0.0" friction="0.0"/>
  </joint>
  <transmission name="l_back_shoulder2_to_shoulder_trans">
    <type>transmission_interface/SimpleTransmission</type>
    <actuator name="back_l_shoulder2_to_shoulder_motor">
      <mechanicalReduction>1</mechanicalReduction>
    </actuator>
    <joint name="l_back_shoulder2_to_shoulder">
      <hardwareInterface>hardware_interface/PositionJointInterface</hardwareInterface>
    </joint>
  </transmission>
  <link name="l_back_shoulder2_box">
    <visual name="l_back_shoulder2_box">
      <origin rpy="0.0 0.0 0.0" xyz="-0.045 -0.02 0.0"/>
      <geometry>
        <box size="0.11 0.05 0.06"/>
      </geometry>
      <material name="yellow"/>
    </visual>
    <collision>
      <origin rpy="0.0 0.0 0.0" xyz="-0.045 -0.02 0.0"/>
      <geometry>
        <box size="0.11 0.05 0.06"/>
      </geometry>
    </collision>
    <inertial>
      <mass value="3"/>
      <inertia ixx="1.0" ixy="0.0" ixz="0.0" iyy="1.0" iyz="0.0" izz="1.0"/>
    </inertial>
  </link>
  <joint name="l_back_shoulder2_base_to_box" type="fixed">
    <origin rpy="0.0 0.0 0.0" xyz="0.14 0.0 0.0"/>
    <parent link="l_back_shoulder2_base"/>
    <child link="l_back_shoulder2_box"/>
  </joint>
  <!-- KNEE -->
  <link name="l_back_knee_base">
    <visual name="l_back_knee_base">
      <origin rpy="0.0 0.0 0.0" xyz="-0.05 0.0 0.0"/>
      <geometry>
        <box size="0.12 0.01 0.06"/>
      </geometry>
      <material name="yellow"/>
    </visual>
    <collision>
      <origin rpy="0.0 0.0 0.0" xyz="-0.05 0.0 0.0"/>
      <geometry>
        <box size="0.12 0.01 0.06"/>
      </geometry>
    </collision>
    <inertial>
      <mass value="4"/>
      <inertia ixx="1.0" ixy="0.0" ixz="0.0" iyy="1.0" iyz="0.0" izz="1.0"/>
    </inertial>
  </link>
  <joint name="l_back_shoulder2_to_knee" type="continuous">
    <axis xyz="0.0 1 0.0"/>
    <origin rpy="0.0 0.0 0.0" xyz="0.0 -0.052 0.0"/>
    <parent link="l_back_shoulder2_box"/>
    <child link="l_back_knee_base"/>
  </joint>
  <transmission name="l_back_shoulder2_to_knee_trans">
    <type>transmission_interface/SimpleTransmission</type>
    <actuator name="back_l_shoulder2_to_knee_motor">
      <mechanicalReduction>1</mechanicalReduction>
    </actuator>
    <joint name="l_back_shoulder2_to_knee">
      <hardwareInterface>hardware_interface/PositionJointInterface</hardwareInterface>
    </joint>
  </transmission>
  <link name="l_back_knee_box">
    <visual name="l_back_knee_box">
      <origin rpy="0.0 0.0 0.0" xyz="0.03 0.02 0.0"/>
      <geometry>
        <box size="0.08 0.05 0.06"/>
      </geometry>
      <material name="yellow"/>
    </visual>
    <collision>
      <origin rpy="0.0 0.0 0.0" xyz="0.03 0.02 0.0"/>
      <geometry>
        <box size="0.08 0.05 0.06"/>
      </geometry>
    </collision>
    <inertial>
      <mass value="0.5"/>
      <inertia ixx="1.0" ixy="0.0" ixz="0.0" iyy="1.0" iyz="0.0" izz="1.0"/>
    </inertial>
  </link>
  <joint name="l_back_knee_base_to_box" type="fixed">
    <origin rpy="0.0 0.0 0.0" xyz="-0.18 0.0 0.0"/>
    <parent link="l_back_knee_base"/>
    <child link="l_back_knee_box"/>
  </joint>
  <!-- ANKLE & TRACK -->
  <link name="l_back_jointed_track">
    <visual name="l_back_jointed_track">
      <origin rpy="0.0 1.57075 1.57075" xyz="0.0 0.0 0.0"/>
      <geometry>
        <cylinder length="0.05" radius="0.03"/>
      </geometry>
      <material name="yellow"/>
    </visual>
    <collision>
      <origin rpy="0.0 1.57075 1.57075" xyz="0.0 0.0 0.0"/>
      <geometry>
        <cylinder length="0.05" radius="0.03"/>
      </geometry>
    </collision>
    <inertial>
      <mass value="0.5"/>
      <inertia ixx="1.0" ixy="0.0" ixz="0.0" iyy="1.0" iyz="0.0" izz="1.0"/>
    </inertial>
  </link>
  <joint name="l_back_ankle" type="continuous">
    <axis xyz="0.0 1 0.0"/>
    <origin rpy="0.0 0.0 0.0" xyz="0.0 -0.032 0.0"/>
    <parent link="l_back_knee_box"/>
    <child link="l_back_jointed_track"/>
  </joint>
  <transmission name="l_back_ankle_trans">
    <type>transmission_interface/SimpleTransmission</type>
    <actuator name="back_l_ankle_motor">
      <mechanicalReduction>1</mechanicalReduction>
    </actuator>
    <joint name="l_back_ankle">
      <hardwareInterface>hardware_interface/PositionJointInterface</hardwareInterface>
    </joint>
  </transmission>
  <link name="l_back_track">
    <visual name="l_back_track">
      <origin rpy="0.0 0.0 0.0" xyz="0.0 0.0 0.0"/>
      <geometry>
        <box size="0.190 0.05 0.06"/>
      </geometry>
      <material name="yellow"/>
    </visual>
    <collision>
      <origin rpy="0.0 0.0 0.0" xyz="0.0 0.0 0.0"/>
      <geometry>
        <box size="0.190 0.05 0.06"/>
      </geometry>
    </collision>
    <inertial>
      <mass value="4.5"/>
      <inertia ixx="1.0" ixy="0.0" ixz="0.0" iyy="1.0" iyz="0.0" izz="1.0"/>
    </inertial>
  </link>
  <joint name="l_back_jointed_track_to_track" type="fixed">
    <origin rpy="0.0 3.1415 0.0" xyz="0.095 0.0 0.0"/>
    <parent link="l_back_jointed_track"/>
    <child link="l_back_track"/>
  </joint>
  <link name="l_back_ends_track">
    <visual name="l_back_ends_track">
      <origin rpy="0.0 1.57075 1.57075" xyz="0.0 0.0 0.0"/>
      <geometry>
        <cylinder length="0.05" radius="0.03"/>
      </geometry>
      <material name="yellow"/>
    </visual>
    <collision>
      <origin rpy="0.0 1.57075 1.57075" xyz="0.0 0.0 0.0"/>
      <geometry>
        <cylinder length="0.05" radius="0.03"/>
      </geometry>
    </collision>
    <inertial>
      <mass value="0.5"/>
      <inertia ixx="1.0" ixy="0.0" ixz="0.0" iyy="1.0" iyz="0.0" izz="1.0"/>
    </inertial>
  </link>
  <joint name="l_back_final_track_joint" type="continuous">
    <axis xyz="0.0 1 0.0"/>
    <origin rpy="0.0 0.0 0.0" xyz="-0.095 0.0 0.0"/>
    <parent link="l_back_track"/>
    <child link="l_back_ends_track"/>
  </joint>
  <transmission name="l_back_final_track_joint_trans">
    <type>transmission_interface/SimpleTransmission</type>
    <actuator name="back_l_final_track_joint_motor">
      <mechanicalReduction>1</mechanicalReduction>
    </actuator>
    <joint name="l_back_final_track_joint">
      <hardwareInterface>hardware_interface/VelocityJointInterface</hardwareInterface>
      <!-- <hardwareInterface>hardware_interface/PositionJointInterface</hardwareInterface> -->
    </joint>
  </transmission>
  <gazebo reference="r_back_ends_track">
    <mu1 value="200.0"/>
    <mu2 value="100.0"/>
    <kp value="10000000.0"/>
    <kd value="1.0"/>
    <material>Gazebo/Grey</material>
  </gazebo>
  <!-- Gazebo plugin for ROS Control -->
  <gazebo>
    <plugin filename="libgazebo_ros_control.so" name="gazebo_ros_control">
      <robotNamespace>/</robotNamespace>
    </plugin>
  </gazebo>
</robot>

