<?xml version="1.0" encoding="utf-8"?>
<!-- =================================================================================== -->
<!-- |    This document was autogenerated by xacro from cricket.xacro                  | -->
<!-- |    EDITING THIS FILE BY HAND IS NOT RECOMMENDED                                 | -->
<!-- =================================================================================== -->
<robot name="A-2085-04" version="1.0">
  <!-- This is a single xacro file you can include to get
  all of the HEBI components -->
  <!-- This automatically loads the gazebo plugin for xacro models
       which include hebi.xacro -->
  <gazebo>
    <plugin filename="libhebi_gazebo_plugin.so" name="hebi_gazebo_plugin"/>
  </gazebo>
  <gazebo>
    <plugin filename="libhebi_gazebo_plugin.so" name="hebi_gazebo_plugin">
      <actuators>
        <actuator family="Cricket" mocked="false" name="L1_J1_shoulder1" type="X8_16"/>
        <actuator family="Cricket" mocked="false" name="L1_J2_shoulder2" type="X8_16"/>
        <actuator family="Cricket" mocked="false" name="L1_J3_knee" type="X8_16"/>
        <actuator family="Cricket" mocked="false" name="L1_J4_ankle" type="X8_16"/>
        <actuator family="Cricket" mocked="false" name="L1_J5_track" type="X8_16"/>
        <actuator family="Cricket" mocked="false" name="L2_J1_shoulder1" type="X8_16"/>
        <actuator family="Cricket" mocked="false" name="L2_J2_shoulder2" type="X8_16"/>
        <actuator family="Cricket" mocked="false" name="L2_J3_knee" type="X8_16"/>
        <actuator family="Cricket" mocked="false" name="L2_J4_ankle" type="X8_16"/>
        <actuator family="Cricket" mocked="false" name="L2_J5_track" type="X8_16"/>
        <actuator family="Cricket" mocked="false" name="L3_J1_shoulder1" type="X8_16"/>
        <actuator family="Cricket" mocked="false" name="L3_J2_shoulder2" type="X8_16"/>
        <actuator family="Cricket" mocked="false" name="L3_J3_knee" type="X8_16"/>
        <actuator family="Cricket" mocked="false" name="L3_J4_ankle" type="X8_16"/>
        <actuator family="Cricket" mocked="false" name="L3_J5_track" type="X8_16"/>
        <actuator family="Cricket" mocked="false" name="L4_J1_shoulder1" type="X8_16"/>
        <actuator family="Cricket" mocked="false" name="L4_J2_shoulder2" type="X8_16"/>
        <actuator family="Cricket" mocked="false" name="L4_J3_knee" type="X8_16"/>
        <actuator family="Cricket" mocked="false" name="L4_J4_ankle" type="X8_16"/>
        <actuator family="Cricket" mocked="false" name="L4_J5_track" type="X8_16"/>
      </actuators>
    </plugin>
  </gazebo>
  <link name="cricket_base">
    <visual>
      <origin rpy="0 0 0" xyz="0 0 0"/>
      <geometry>
        <box size="0.370 0.285 0.150"/>
      </geometry>
      <material name="black">
        <color rgba="0.1 0.1 0.1 1"/>
      </material>
    </visual>
    <collision>
      <origin rpy="0 0 0" xyz="0 0 0"/>
      <geometry>
        <box size="0.370 0.285 0.150"/>
      </geometry>
    </collision>
  </link>
  <link name="cricket_base_inertia">
    <inertial>
      <mass value="2.0"/>
      <origin rpy="0 0 0" xyz="0 0 0"/>
      <inertia ixx="0.001" ixy="0" ixz="0" iyy="0.001" iyz="0" izz="0.001"/>
    </inertial>
  </link>
  <joint name="cricket_base_inertia_joint" type="fixed">
    <parent link="cricket_base"/>
    <child link="cricket_base_inertia"/>
  </joint>
  <joint name="base_leg1_joint" type="fixed">
    <origin rpy="-1.57079632679 0 0" xyz="0.135 0.100 0.030"/>
    <parent link="cricket_base"/>
    <child link="leg1_base_bracket/INPUT_INTERFACE"/>
  </joint>
  <link name="leg1_base_bracket/INPUT_INTERFACE">
    <visual>
      <origin rpy="0 0 0" xyz="0.0 0.0 0.01"/>
      <geometry>
        <box size="0.05 0.05 0.02"/>
      </geometry>
      <material name="beige">
        <color rgba="0.96 0.945 0.871 1"/>
      </material>
    </visual>
    <inertial>
      <mass value="0.05"/>
      <origin rpy="0 0 0" xyz="0 0 0"/>
      <inertia ixx="0.001" ixy="0" ixz="0" iyy="0.001" iyz="0" izz="0.001"/>
    </inertial>
  </link>
  <joint name="leg1_base_bracket_child_joint" type="fixed">
    <origin rpy="0 0 0" xyz="0.0 0.0 0.02"/>
    <parent link="leg1_base_bracket/INPUT_INTERFACE"/>
    <child link="leg1_base_shoulder1/INPUT_INTERFACE"/>
  </joint>
  <link name="leg1_base_shoulder1/INPUT_INTERFACE">
    <!-- Input Cap -->
    <visual>
      <origin rpy="0 0 0" xyz="0 0 0"/>
      <geometry>
        <mesh filename="package://hebi_description/meshes/A-2038-02.stl"/>
      </geometry>
      <material name="black">
        <color rgba="0.1 0.1 0.1 1"/>
      </material>
    </visual>
    <collision>
      <origin rpy="0 0 0" xyz="0 0 0"/>
      <geometry>
        <mesh filename="package://hebi_description/meshes/A-2038-02.stl"/>
      </geometry>
    </collision>
    <!-- Link Pipe -->
    <visual>
      <origin rpy="0 1.57075 0" xyz="0.0375 0 0.02"/>
      <geometry>
        <cylinder length="0.0496" radius=".016"/>
      </geometry>
      <material name="black">
        <color rgba="0.1 0.1 0.1 1"/>
      </material>
    </visual>
    <collision>
      <origin rpy="0 1.57075 0" xyz="0.0375 0 0.02"/>
      <geometry>
        <cylinder length="0.0496" radius=".016"/>
      </geometry>
    </collision>
    <!-- Output Cap -->
    <visual>
      <origin rpy="1.57079632679 4.71238898038 1.57079632679" xyz="0.075 0 0.02"/>
      <geometry>
        <mesh filename="package://hebi_description/meshes/A-2226-01.stl" scale="0.001 0.001 0.001"/>
      </geometry>
      <material name="black">
        <color rgba="0.1 0.1 0.1 1"/>
      </material>
    </visual>
    <collision>
      <origin rpy="1.57079632679 4.71238898038 1.57079632679" xyz="0.075 0 0.02"/>
      <geometry>
        <mesh filename="package://hebi_description/meshes/A-2039-02.stl"/>
      </geometry>
    </collision>
    <!-- Approximate inertia as thin rod about x axis -->
    <inertial>
      <origin rpy="0 0 0" xyz="0.0375 0 0.02"/>
      <mass value="0.302"/>
      <inertia ixx="0.0" ixy="0.0" ixz="0.0" iyy="0.0001415625" iyz="0.0" izz="0.0001415625"/>
    </inertial>
  </link>
  <gazebo reference="leg1_base_shoulder1/INPUT_INTERFACE">
    <material>Gazebo/Black</material>
  </gazebo>
  <joint name="leg1_base_shoulder1/OUTPUT_JOINT" type="fixed">
    <parent link="leg1_base_shoulder1/INPUT_INTERFACE"/>
    <child link="Cricket/L1_J1_shoulder1/INPUT_INTERFACE"/>
    <origin rpy="1.57079632679 4.71238898038 1.57079632679" xyz="0.075 0 0.02"/>
  </joint>
  <gazebo reference="leg1_base_shoulder1/OUTPUT_JOINT">
    <disableFixedJointLumping>true</disableFixedJointLumping>
    <preserveFixedJoint>true</preserveFixedJoint>
  </gazebo>
  <link name="Cricket/L1_J1_shoulder1/INPUT_INTERFACE">
    <visual>
      <origin rpy="0 0 0" xyz="0 0 0"/>
      <geometry>
        <mesh filename="package://hebi_description/meshes/X8.stl" scale="0.001 0.001 0.001"/>
      </geometry>
      <material name="red">
        <color rgba=".82 0.06 0.06 1"/>
      </material>
    </visual>
    <collision>
      <origin rpy="0 0 0" xyz="0 0 0"/>
      <geometry>
        <mesh filename="package://hebi_description/meshes/X8.stl" scale="0.001 0.001 0.001"/>
      </geometry>
    </collision>
    <inertial>
      <mass value="0.5"/>
      <origin rpy="0 0 0" xyz="-0.0145 -0.0031 0.0242"/>
      <inertia ixx="0.000246" ixy="0.0000444" ixz="0.0000266" iyy="0.000380" iyz="0.00000422" izz="0.000463"/>
    </inertial>
  </link>
  <gazebo reference="Cricket/L1_J1_shoulder1/INPUT_INTERFACE">
    <material>Gazebo/Red</material>
  </gazebo>
  <link name="HEBI_SIM/Cricket/L1_J1_shoulder1/X8_16">
    <visual>
      <origin rpy="0 0 0" xyz="-0.03 0 0.02"/>
      <geometry>
        <sphere radius="0.001"/>
      </geometry>
    </visual>
    <inertial>
      <mass value="0.001"/>
      <origin rpy="0 0 0" xyz="0 0 0"/>
      <inertia ixx="0.000001" ixy="0" ixz="0" iyy="0.000001" iyz="0" izz="0.000001"/>
    </inertial>
  </link>
  <joint name="HEBI_SIM_JOINT/Cricket/L1_J1_shoulder1" type="fixed">
    <parent link="Cricket/L1_J1_shoulder1/INPUT_INTERFACE"/>
    <child link="HEBI_SIM/Cricket/L1_J1_shoulder1/X8_16"/>
    <origin rpy="0 0 0" xyz="0 0 0"/>
  </joint>
  <gazebo reference="HEBI_SIM_JOINT/Cricket/L1_J1_shoulder1">
    <disableFixedJointLumping>true</disableFixedJointLumping>
    <preserveFixedJoint>true</preserveFixedJoint>
  </gazebo>
  <joint name="Cricket/L1_J1_shoulder1" type="continuous">
    <parent link="Cricket/L1_J1_shoulder1/INPUT_INTERFACE"/>
    <child link="leg_1_shoulder1_shoulder2/INPUT_INTERFACE"/>
    <origin rpy="0 0 0" xyz="0 0 0.045"/>
    <axis xyz="0 0 1"/>
    <limit effort="38" velocity="1.571"/>
    <dynamics damping="0.5" friction="0.5"/>
  </joint>
  <link name="leg_1_shoulder1_shoulder2/INPUT_INTERFACE">
    <visual>
      <origin rpy="1.57079632679 0 1.57079632679" xyz="0 0 0.005"/>
      <geometry>
        <mesh filename="package://hebi_description/meshes/PM-2149-01.stl" scale="0.001 0.001 0.001"/>
      </geometry>
      <material name="black">
        <color rgba="0.1 0.1 0.1 1"/>
      </material>
    </visual>
    <visual>
      <origin rpy="1.57079632679 0 3.14159265359" xyz="0 -.03 .04"/>
      <geometry>
        <mesh filename="package://hebi_description/meshes/PM-2150-01L.stl" scale="0.001 0.001 0.001"/>
      </geometry>
      <material name="black">
        <color rgba="0.1 0.1 0.1 1"/>
      </material>
    </visual>
    <collision>
      <origin rpy="1.57079632679 0 1.57079632679" xyz="0 0 0.005"/>
      <geometry>
        <mesh filename="package://hebi_description/meshes/PM-2149-01.stl" scale="0.001 0.001 0.001"/>
      </geometry>
    </collision>
    <collision>
      <origin rpy="1.57079632679 0 3.14159265359" xyz="0 -.03 .04"/>
      <geometry>
        <mesh filename="package://hebi_description/meshes/PM-2150-01L.stl" scale="0.001 0.001 0.001"/>
      </geometry>
    </collision>
    <!-- NOTE: inertia is just modelled as small sphere, and could be improved. -->
    <inertial>
      <origin rpy="0 0 0" xyz="0 -0.01125 .0275"/>
      <mass value="0.215"/>
      <inertia ixx="0.0003096" ixy="0.0" ixz="0.0" iyy="0.0003096" iyz="0.0" izz="0.0003096"/>
    </inertial>
  </link>
  <gazebo reference="leg_1_shoulder1_shoulder2/INPUT_INTERFACE">
    <material>Gazebo/Black</material>
  </gazebo>
  <joint name="leg_1_shoulder1_shoulder2/OUTPUT_INTERFACE" type="fixed">
    <parent link="leg_1_shoulder1_shoulder2/INPUT_INTERFACE"/>
    <child link="Cricket/L1_J2_shoulder2/INPUT_INTERFACE"/>
    <origin rpy="-1.57079632679 0 0" xyz="0 -.0225 .055"/>
  </joint>
  <gazebo reference="leg_1_shoulder1_shoulder2/OUTPUT_INTERFACE">
    <disableFixedJointLumping>true</disableFixedJointLumping>
    <preserveFixedJoint>true</preserveFixedJoint>
  </gazebo>
  <link name="Cricket/L1_J2_shoulder2/INPUT_INTERFACE">
    <visual>
      <origin rpy="0 0 0" xyz="0 0 0"/>
      <geometry>
        <mesh filename="package://hebi_description/meshes/X8.stl" scale="0.001 0.001 0.001"/>
      </geometry>
      <material name="red">
        <color rgba=".82 0.06 0.06 1"/>
      </material>
    </visual>
    <collision>
      <origin rpy="0 0 0" xyz="0 0 0"/>
      <geometry>
        <mesh filename="package://hebi_description/meshes/X8.stl" scale="0.001 0.001 0.001"/>
      </geometry>
    </collision>
    <inertial>
      <mass value="0.5"/>
      <origin rpy="0 0 0" xyz="-0.0145 -0.0031 0.0242"/>
      <inertia ixx="0.000246" ixy="0.0000444" ixz="0.0000266" iyy="0.000380" iyz="0.00000422" izz="0.000463"/>
    </inertial>
  </link>
  <gazebo reference="Cricket/L1_J2_shoulder2/INPUT_INTERFACE">
    <material>Gazebo/Red</material>
  </gazebo>
  <link name="HEBI_SIM/Cricket/L1_J2_shoulder2/X8_16">
    <visual>
      <origin rpy="0 0 0" xyz="-0.03 0 0.02"/>
      <geometry>
        <sphere radius="0.001"/>
      </geometry>
    </visual>
    <inertial>
      <mass value="0.001"/>
      <origin rpy="0 0 0" xyz="0 0 0"/>
      <inertia ixx="0.000001" ixy="0" ixz="0" iyy="0.000001" iyz="0" izz="0.000001"/>
    </inertial>
  </link>
  <joint name="HEBI_SIM_JOINT/Cricket/L1_J2_shoulder2" type="fixed">
    <parent link="Cricket/L1_J2_shoulder2/INPUT_INTERFACE"/>
    <child link="HEBI_SIM/Cricket/L1_J2_shoulder2/X8_16"/>
    <origin rpy="0 0 0" xyz="0 0 0"/>
  </joint>
  <gazebo reference="HEBI_SIM_JOINT/Cricket/L1_J2_shoulder2">
    <disableFixedJointLumping>true</disableFixedJointLumping>
    <preserveFixedJoint>true</preserveFixedJoint>
  </gazebo>
  <joint name="Cricket/L1_J2_shoulder2" type="continuous">
    <parent link="Cricket/L1_J2_shoulder2/INPUT_INTERFACE"/>
    <child link="leg_1_knee_to_link_spacer/INPUT_INTERFACE"/>
    <origin rpy="0 0 0" xyz="0 0 0.045"/>
    <axis xyz="0 0 1"/>
    <limit effort="38" velocity="1.571"/>
    <dynamics damping="0.5" friction="0.5"/>
  </joint>
  <link name="leg_1_knee_to_link_spacer/INPUT_INTERFACE">
    <visual>
      <origin rpy="0 0 0" xyz="0.0 0.0 0.01"/>
      <geometry>
        <box size="0.05 0.05 0.02"/>
      </geometry>
      <material name="beige">
        <color rgba="0.96 0.945 0.871 1"/>
      </material>
    </visual>
    <inertial>
      <mass value="0.05"/>
      <origin rpy="0 0 0" xyz="0 0 0"/>
      <inertia ixx="0.001" ixy="0" ixz="0" iyy="0.001" iyz="0" izz="0.001"/>
    </inertial>
  </link>
  <joint name="leg_1_knee_to_link_spacer_child_joint" type="fixed">
    <origin rpy="0 0 0" xyz="0.0 0.0 0.02"/>
    <parent link="leg_1_knee_to_link_spacer/INPUT_INTERFACE"/>
    <child link="leg_1_shoulder2_knee/INPUT_INTERFACE"/>
  </joint>
  <link name="leg_1_shoulder2_knee/INPUT_INTERFACE">
    <!-- Input Cap -->
    <visual>
      <origin rpy="0 0 0" xyz="0 0 0"/>
      <geometry>
        <mesh filename="package://hebi_description/meshes/A-2038-02.stl"/>
      </geometry>
      <material name="black">
        <color rgba="0.1 0.1 0.1 1"/>
      </material>
    </visual>
    <collision>
      <origin rpy="0 0 0" xyz="0 0 0"/>
      <geometry>
        <mesh filename="package://hebi_description/meshes/A-2038-02.stl"/>
      </geometry>
    </collision>
    <!-- Link Pipe -->
    <visual>
      <origin rpy="0 1.57075 0" xyz="0.075 0 0.02"/>
      <geometry>
        <cylinder length="0.1246" radius=".016"/>
      </geometry>
      <material name="black">
        <color rgba="0.1 0.1 0.1 1"/>
      </material>
    </visual>
    <collision>
      <origin rpy="0 1.57075 0" xyz="0.075 0 0.02"/>
      <geometry>
        <cylinder length="0.1246" radius=".016"/>
      </geometry>
    </collision>
    <!-- Output Cap -->
    <visual>
      <origin rpy="0 0 0" xyz="0.15 0.0 0.04"/>
      <geometry>
        <mesh filename="package://hebi_description/meshes/A-2039-02.stl"/>
      </geometry>
      <material name="black">
        <color rgba="0.1 0.1 0.1 1"/>
      </material>
    </visual>
    <collision>
      <origin rpy="0 0 0" xyz="0.15 0.0 0.04"/>
      <geometry>
        <mesh filename="package://hebi_description/meshes/A-2039-02.stl"/>
      </geometry>
    </collision>
    <!-- Approximate inertia as thin rod about x axis -->
    <inertial>
      <origin rpy="0 0 0" xyz="0.075 0 0.02"/>
      <mass value="0.332"/>
      <inertia ixx="0.0" ixy="0.0" ixz="0.0" iyy="0.0006225" iyz="0.0" izz="0.0006225"/>
    </inertial>
  </link>
  <gazebo reference="leg_1_shoulder2_knee/INPUT_INTERFACE">
    <material>Gazebo/Black</material>
  </gazebo>
  <joint name="leg_1_shoulder2_knee/OUTPUT_JOINT" type="fixed">
    <parent link="leg_1_shoulder2_knee/INPUT_INTERFACE"/>
    <child link="Cricket/L1_J3_knee/INPUT_INTERFACE"/>
    <origin rpy="0 0 0" xyz="0.15 -0.0 0.04"/>
  </joint>
  <gazebo reference="leg_1_shoulder2_knee/OUTPUT_JOINT">
    <disableFixedJointLumping>true</disableFixedJointLumping>
    <preserveFixedJoint>true</preserveFixedJoint>
  </gazebo>
  <link name="Cricket/L1_J3_knee/INPUT_INTERFACE">
    <visual>
      <origin rpy="0 0 0" xyz="0 0 0"/>
      <geometry>
        <mesh filename="package://hebi_description/meshes/X8.stl" scale="0.001 0.001 0.001"/>
      </geometry>
      <material name="red">
        <color rgba=".82 0.06 0.06 1"/>
      </material>
    </visual>
    <collision>
      <origin rpy="0 0 0" xyz="0 0 0"/>
      <geometry>
        <mesh filename="package://hebi_description/meshes/X8.stl" scale="0.001 0.001 0.001"/>
      </geometry>
    </collision>
    <inertial>
      <mass value="0.5"/>
      <origin rpy="0 0 0" xyz="-0.0145 -0.0031 0.0242"/>
      <inertia ixx="0.000246" ixy="0.0000444" ixz="0.0000266" iyy="0.000380" iyz="0.00000422" izz="0.000463"/>
    </inertial>
  </link>
  <gazebo reference="Cricket/L1_J3_knee/INPUT_INTERFACE">
    <material>Gazebo/Red</material>
  </gazebo>
  <link name="HEBI_SIM/Cricket/L1_J3_knee/X8_16">
    <visual>
      <origin rpy="0 0 0" xyz="-0.03 0 0.02"/>
      <geometry>
        <sphere radius="0.001"/>
      </geometry>
    </visual>
    <inertial>
      <mass value="0.001"/>
      <origin rpy="0 0 0" xyz="0 0 0"/>
      <inertia ixx="0.000001" ixy="0" ixz="0" iyy="0.000001" iyz="0" izz="0.000001"/>
    </inertial>
  </link>
  <joint name="HEBI_SIM_JOINT/Cricket/L1_J3_knee" type="fixed">
    <parent link="Cricket/L1_J3_knee/INPUT_INTERFACE"/>
    <child link="HEBI_SIM/Cricket/L1_J3_knee/X8_16"/>
    <origin rpy="0 0 0" xyz="0 0 0"/>
  </joint>
  <gazebo reference="HEBI_SIM_JOINT/Cricket/L1_J3_knee">
    <disableFixedJointLumping>true</disableFixedJointLumping>
    <preserveFixedJoint>true</preserveFixedJoint>
  </gazebo>
  <joint name="Cricket/L1_J3_knee" type="continuous">
    <parent link="Cricket/L1_J3_knee/INPUT_INTERFACE"/>
    <child link="leg1_knee_ankle/INPUT_INTERFACE"/>
    <origin rpy="0 0 0" xyz="0 0 0.045"/>
    <axis xyz="0 0 1"/>
    <limit effort="38" velocity="1.571"/>
    <dynamics damping="0.5" friction="0.5"/>
  </joint>
  <link name="leg1_knee_ankle/INPUT_INTERFACE">
    <!-- Input Cap -->
    <visual>
      <origin rpy="0 0 0" xyz="0 0 0"/>
      <geometry>
        <mesh filename="package://hebi_description/meshes/A-2038-02.stl"/>
      </geometry>
      <material name="black">
        <color rgba="0.1 0.1 0.1 1"/>
      </material>
    </visual>
    <collision>
      <origin rpy="0 0 0" xyz="0 0 0"/>
      <geometry>
        <mesh filename="package://hebi_description/meshes/A-2038-02.stl"/>
      </geometry>
    </collision>
    <!-- Link Pipe -->
    <visual>
      <origin rpy="0 1.57075 0" xyz="0.1375 0 0.02"/>
      <geometry>
        <cylinder length="0.2496" radius=".016"/>
      </geometry>
      <material name="black">
        <color rgba="0.1 0.1 0.1 1"/>
      </material>
    </visual>
    <collision>
      <origin rpy="0 1.57075 0" xyz="0.1375 0 0.02"/>
      <geometry>
        <cylinder length="0.2496" radius=".016"/>
      </geometry>
    </collision>
    <!-- Output Cap -->
    <visual>
      <origin rpy="0 0 0" xyz="0.275 0.0 0.04"/>
      <geometry>
        <mesh filename="package://hebi_description/meshes/A-2039-02.stl"/>
      </geometry>
      <material name="black">
        <color rgba="0.1 0.1 0.1 1"/>
      </material>
    </visual>
    <collision>
      <origin rpy="0 0 0" xyz="0.275 0.0 0.04"/>
      <geometry>
        <mesh filename="package://hebi_description/meshes/A-2039-02.stl"/>
      </geometry>
    </collision>
    <!-- Approximate inertia as thin rod about x axis -->
    <inertial>
      <origin rpy="0 0 0" xyz="0.1375 0 0.02"/>
      <mass value="0.382"/>
      <inertia ixx="0.0" ixy="0.0" ixz="0.0" iyy="0.00240739583333" iyz="0.0" izz="0.00240739583333"/>
    </inertial>
  </link>
  <gazebo reference="leg1_knee_ankle/INPUT_INTERFACE">
    <material>Gazebo/Black</material>
  </gazebo>
  <joint name="leg1_knee_ankle/OUTPUT_JOINT" type="fixed">
    <parent link="leg1_knee_ankle/INPUT_INTERFACE"/>
    <child link="leg1_ankle_spacer/INPUT_INTERFACE"/>
    <origin rpy="0 0 0" xyz="0.275 -0.0 0.04"/>
  </joint>
  <gazebo reference="leg1_knee_ankle/OUTPUT_JOINT">
    <disableFixedJointLumping>true</disableFixedJointLumping>
    <preserveFixedJoint>true</preserveFixedJoint>
  </gazebo>
  <link name="leg1_ankle_spacer/INPUT_INTERFACE">
    <inertial>
      <mass value="0.01"/>
      <origin rpy="0 0 0" xyz="0 0 0"/>
      <inertia ixx="0.001" ixy="0" ixz="0" iyy="0.001" iyz="0" izz="0.001"/>
    </inertial>
  </link>
  <link name="Cricket/L1_J4_ankle/INPUT_INTERFACE">
    <visual>
      <origin rpy="0 0 0" xyz="0 0 0"/>
      <geometry>
        <mesh filename="package://hebi_description/meshes/X8.stl" scale="0.001 0.001 0.001"/>
      </geometry>
      <material name="red">
        <color rgba=".82 0.06 0.06 1"/>
      </material>
    </visual>
    <collision>
      <origin rpy="0 0 0" xyz="0 0 0"/>
      <geometry>
        <mesh filename="package://hebi_description/meshes/X8.stl" scale="0.001 0.001 0.001"/>
      </geometry>
    </collision>
    <inertial>
      <mass value="0.5"/>
      <origin rpy="0 0 0" xyz="-0.0145 -0.0031 0.0242"/>
      <inertia ixx="0.000246" ixy="0.0000444" ixz="0.0000266" iyy="0.000380" iyz="0.00000422" izz="0.000463"/>
    </inertial>
  </link>
  <gazebo reference="Cricket/L1_J4_ankle/INPUT_INTERFACE">
    <material>Gazebo/Red</material>
  </gazebo>
  <link name="HEBI_SIM/Cricket/L1_J4_ankle/X8_16">
    <visual>
      <origin rpy="0 0 0" xyz="-0.03 0 0.02"/>
      <geometry>
        <sphere radius="0.001"/>
      </geometry>
    </visual>
    <inertial>
      <mass value="0.001"/>
      <origin rpy="0 0 0" xyz="0 0 0"/>
      <inertia ixx="0.000001" ixy="0" ixz="0" iyy="0.000001" iyz="0" izz="0.000001"/>
    </inertial>
  </link>
  <joint name="HEBI_SIM_JOINT/Cricket/L1_J4_ankle" type="fixed">
    <parent link="Cricket/L1_J4_ankle/INPUT_INTERFACE"/>
    <child link="HEBI_SIM/Cricket/L1_J4_ankle/X8_16"/>
    <origin rpy="0 0 0" xyz="0 0 0"/>
  </joint>
  <gazebo reference="HEBI_SIM_JOINT/Cricket/L1_J4_ankle">
    <disableFixedJointLumping>true</disableFixedJointLumping>
    <preserveFixedJoint>true</preserveFixedJoint>
  </gazebo>
  <joint name="Cricket/L1_J4_ankle" type="continuous">
    <parent link="leg1_ankle_spacer/INPUT_INTERFACE"/>
    <child link="Cricket/L1_J4_ankle/INPUT_INTERFACE"/>
    <origin rpy="0 3.14159265359 0" xyz="0 0 0.045"/>
    <axis xyz="0 0 1"/>
    <limit effort="38" velocity="1.571"/>
    <dynamics damping="0.5" friction="0.5"/>
  </joint>
  <joint name="Cricket/L1_J4_ankle_fixed" type="fixed">
    <parent link="Cricket/L1_J4_ankle/INPUT_INTERFACE"/>
    <child link="leg1_track_bracket_1/INPUT_INTERFACE"/>
    <origin rpy="0 0 0" xyz="0 0 0"/>
  </joint>
  <link name="leg1_track_bracket_1/INPUT_INTERFACE">
    <visual>
      <origin rpy="0 0 0" xyz="-0.0685 0.0 -0.005"/>
      <geometry>
        <box size="0.15 0.05 0.01"/>
      </geometry>
      <material name="beige">
        <color rgba="0.96 0.945 0.871 1"/>
      </material>
    </visual>
    <inertial>
      <mass value="0.3"/>
      <origin rpy="0 0 0" xyz="0 0 0"/>
      <inertia ixx="0.001" ixy="0" ixz="0" iyy="0.001" iyz="0" izz="0.001"/>
    </inertial>
  </link>
  <joint name="leg1_track_bracket_1_child_joint" type="fixed">
    <origin rpy="0 0 0" xyz="-0.137 0.0 -0.01"/>
    <parent link="leg1_track_bracket_1/INPUT_INTERFACE"/>
    <child link="leg1_track_bracket_2/INPUT_INTERFACE"/>
  </joint>
  <link name="leg1_track_bracket_2/INPUT_INTERFACE">
    <visual>
      <origin rpy="0 0 0" xyz="0.0 0.0 0.025"/>
      <geometry>
        <box size="0.08 0.05 0.05"/>
      </geometry>
      <material name="beige">
        <color rgba="0.96 0.945 0.871 1"/>
      </material>
    </visual>
    <inertial>
      <mass value="0.3"/>
      <origin rpy="0 0 0" xyz="0 0 0"/>
      <inertia ixx="0.001" ixy="0" ixz="0" iyy="0.001" iyz="0" izz="0.001"/>
    </inertial>
  </link>
  <joint name="leg1_track_bracket_2_child_joint" type="fixed">
    <origin rpy="0 0 0" xyz="0.0 0.0 0.05"/>
    <parent link="leg1_track_bracket_2/INPUT_INTERFACE"/>
    <child link="leg1_track_bracket_3/INPUT_INTERFACE"/>
  </joint>
  <link name="leg1_track_bracket_3/INPUT_INTERFACE">
    <visual>
      <origin rpy="0 0 0" xyz="-0.0685 0.0 -0.005"/>
      <geometry>
        <box size="0.15 0.05 0.01"/>
      </geometry>
      <material name="beige">
        <color rgba="0.96 0.945 0.871 1"/>
      </material>
    </visual>
    <inertial>
      <mass value="0.3"/>
      <origin rpy="0 0 0" xyz="0 0 0"/>
      <inertia ixx="0.001" ixy="0" ixz="0" iyy="0.001" iyz="0" izz="0.001"/>
    </inertial>
  </link>
  <joint name="leg1_track_bracket_3_child_joint" type="fixed">
    <origin rpy="0 3.14159265359 0" xyz="-0.137 0.0 -0.01"/>
    <parent link="leg1_track_bracket_3/INPUT_INTERFACE"/>
    <child link="Cricket/L1_J5_track/INPUT_INTERFACE"/>
  </joint>
  <link name="Cricket/L1_J5_track/INPUT_INTERFACE">
    <visual>
      <origin rpy="0 0 0" xyz="0 0 0"/>
      <geometry>
        <mesh filename="package://hebi_description/meshes/X8.stl" scale="0.001 0.001 0.001"/>
      </geometry>
      <material name="red">
        <color rgba=".82 0.06 0.06 1"/>
      </material>
    </visual>
    <collision>
      <origin rpy="0 0 0" xyz="0 0 0"/>
      <geometry>
        <mesh filename="package://hebi_description/meshes/X8.stl" scale="0.001 0.001 0.001"/>
      </geometry>
    </collision>
    <inertial>
      <mass value="0.5"/>
      <origin rpy="0 0 0" xyz="-0.0145 -0.0031 0.0242"/>
      <inertia ixx="0.000246" ixy="0.0000444" ixz="0.0000266" iyy="0.000380" iyz="0.00000422" izz="0.000463"/>
    </inertial>
  </link>
  <gazebo reference="Cricket/L1_J5_track/INPUT_INTERFACE">
    <material>Gazebo/Red</material>
  </gazebo>
  <link name="HEBI_SIM/Cricket/L1_J5_track/X8_16">
    <visual>
      <origin rpy="0 0 0" xyz="-0.03 0 0.02"/>
      <geometry>
        <sphere radius="0.001"/>
      </geometry>
    </visual>
    <inertial>
      <mass value="0.001"/>
      <origin rpy="0 0 0" xyz="0 0 0"/>
      <inertia ixx="0.000001" ixy="0" ixz="0" iyy="0.000001" iyz="0" izz="0.000001"/>
    </inertial>
  </link>
  <joint name="HEBI_SIM_JOINT/Cricket/L1_J5_track" type="fixed">
    <parent link="Cricket/L1_J5_track/INPUT_INTERFACE"/>
    <child link="HEBI_SIM/Cricket/L1_J5_track/X8_16"/>
    <origin rpy="0 0 0" xyz="0 0 0"/>
  </joint>
  <gazebo reference="HEBI_SIM_JOINT/Cricket/L1_J5_track">
    <disableFixedJointLumping>true</disableFixedJointLumping>
    <preserveFixedJoint>true</preserveFixedJoint>
  </gazebo>
  <joint name="Cricket/L1_J5_track" type="continuous">
    <parent link="Cricket/L1_J5_track/INPUT_INTERFACE"/>
    <child link="leg1_drive_pulley/INPUT_INTERFACE"/>
    <origin rpy="0 0 0" xyz="0 0 0.045"/>
    <axis xyz="0 0 1"/>
    <limit effort="38" velocity="1.571"/>
    <dynamics damping="0.5" friction="0.5"/>
  </joint>
  <link name="leg1_drive_pulley/INPUT_INTERFACE">
    <visual>
      <origin rpy="0 0 0" xyz="0 0 0.020"/>
      <geometry>
        <cylinder length="0.033" radius="0.068"/>
      </geometry>
      <material name="black">
        <color rgba="0.1 0.1 0.1 1"/>
      </material>
    </visual>
    <collision>
      <origin rpy="0 0 0" xyz="0 0 0.020"/>
      <geometry>
        <cylinder length="0.033" radius="0.068"/>
      </geometry>
    </collision>
    <inertial>
      <mass value="0.1"/>
      <origin rpy="0 0 0" xyz="0 0 0"/>
      <inertia ixx="0.001" ixy="0" ixz="0" iyy="0.001" iyz="0" izz="0.001"/>
    </inertial>
  </link>
  <link name="leg1_idle_pulley">
    <visual>
      <origin rpy="0 0 0" xyz="0.0 0.0 -0.03"/>
      <geometry>
        <cylinder length="0.033" radius="0.068"/>
      </geometry>
      <material name="black">
        <color rgba="0.1 0.1 0.1 1"/>
      </material>
    </visual>
    <inertial>
      <mass value="0.1"/>
      <origin rpy="0 0 0" xyz="0 0 0"/>
      <inertia ixx="0.001" ixy="0" ixz="0" iyy="0.001" iyz="0" izz="0.001"/>
    </inertial>
  </link>
  <joint name="leg1_idle_pulley_joint" type="continuous">
    <origin rpy="0 0 0" xyz="0 0 0"/>
    <parent link="Cricket/L1_J4_ankle/INPUT_INTERFACE"/>
    <child link="leg1_idle_pulley"/>
    <axis xyz="0 0 1"/>
  </joint>
  <joint name="base_leg2_joint" type="fixed">
    <origin rpy="1.57079632679 0 0" xyz="0.135 -0.100 0.030"/>
    <parent link="cricket_base"/>
    <child link="leg2_base_bracket/INPUT_INTERFACE"/>
  </joint>
  <link name="leg2_base_bracket/INPUT_INTERFACE">
    <visual>
      <origin rpy="0 0 0" xyz="0.0 0.0 0.01"/>
      <geometry>
        <box size="0.05 0.05 0.02"/>
      </geometry>
      <material name="beige">
        <color rgba="0.96 0.945 0.871 1"/>
      </material>
    </visual>
    <inertial>
      <mass value="0.05"/>
      <origin rpy="0 0 0" xyz="0 0 0"/>
      <inertia ixx="0.001" ixy="0" ixz="0" iyy="0.001" iyz="0" izz="0.001"/>
    </inertial>
  </link>
  <joint name="leg2_base_bracket_child_joint" type="fixed">
    <origin rpy="0 0 0" xyz="0.0 0.0 0.02"/>
    <parent link="leg2_base_bracket/INPUT_INTERFACE"/>
    <child link="leg2_base_shoulder1/INPUT_INTERFACE"/>
  </joint>
  <link name="leg2_base_shoulder1/INPUT_INTERFACE">
    <!-- Input Cap -->
    <visual>
      <origin rpy="0 0 0" xyz="0 0 0"/>
      <geometry>
        <mesh filename="package://hebi_description/meshes/A-2038-02.stl"/>
      </geometry>
      <material name="black">
        <color rgba="0.1 0.1 0.1 1"/>
      </material>
    </visual>
    <collision>
      <origin rpy="0 0 0" xyz="0 0 0"/>
      <geometry>
        <mesh filename="package://hebi_description/meshes/A-2038-02.stl"/>
      </geometry>
    </collision>
    <!-- Link Pipe -->
    <visual>
      <origin rpy="0 1.57075 0" xyz="0.0375 0 0.02"/>
      <geometry>
        <cylinder length="0.0496" radius=".016"/>
      </geometry>
      <material name="black">
        <color rgba="0.1 0.1 0.1 1"/>
      </material>
    </visual>
    <collision>
      <origin rpy="0 1.57075 0" xyz="0.0375 0 0.02"/>
      <geometry>
        <cylinder length="0.0496" radius=".016"/>
      </geometry>
    </collision>
    <!-- Output Cap -->
    <visual>
      <origin rpy="1.57079632679 4.71238898038 1.57079632679" xyz="0.075 0 0.02"/>
      <geometry>
        <mesh filename="package://hebi_description/meshes/A-2226-01.stl" scale="0.001 0.001 0.001"/>
      </geometry>
      <material name="black">
        <color rgba="0.1 0.1 0.1 1"/>
      </material>
    </visual>
    <collision>
      <origin rpy="1.57079632679 4.71238898038 1.57079632679" xyz="0.075 0 0.02"/>
      <geometry>
        <mesh filename="package://hebi_description/meshes/A-2039-02.stl"/>
      </geometry>
    </collision>
    <!-- Approximate inertia as thin rod about x axis -->
    <inertial>
      <origin rpy="0 0 0" xyz="0.0375 0 0.02"/>
      <mass value="0.302"/>
      <inertia ixx="0.0" ixy="0.0" ixz="0.0" iyy="0.0001415625" iyz="0.0" izz="0.0001415625"/>
    </inertial>
  </link>
  <gazebo reference="leg2_base_shoulder1/INPUT_INTERFACE">
    <material>Gazebo/Black</material>
  </gazebo>
  <joint name="leg2_base_shoulder1/OUTPUT_JOINT" type="fixed">
    <parent link="leg2_base_shoulder1/INPUT_INTERFACE"/>
    <child link="Cricket/L2_J1_shoulder1/INPUT_INTERFACE"/>
    <origin rpy="1.57079632679 4.71238898038 1.57079632679" xyz="0.075 0 0.02"/>
  </joint>
  <gazebo reference="leg2_base_shoulder1/OUTPUT_JOINT">
    <disableFixedJointLumping>true</disableFixedJointLumping>
    <preserveFixedJoint>true</preserveFixedJoint>
  </gazebo>
  <link name="Cricket/L2_J1_shoulder1/INPUT_INTERFACE">
    <visual>
      <origin rpy="0 0 0" xyz="0 0 0"/>
      <geometry>
        <mesh filename="package://hebi_description/meshes/X8.stl" scale="0.001 0.001 0.001"/>
      </geometry>
      <material name="red">
        <color rgba=".82 0.06 0.06 1"/>
      </material>
    </visual>
    <collision>
      <origin rpy="0 0 0" xyz="0 0 0"/>
      <geometry>
        <mesh filename="package://hebi_description/meshes/X8.stl" scale="0.001 0.001 0.001"/>
      </geometry>
    </collision>
    <inertial>
      <mass value="0.5"/>
      <origin rpy="0 0 0" xyz="-0.0145 -0.0031 0.0242"/>
      <inertia ixx="0.000246" ixy="0.0000444" ixz="0.0000266" iyy="0.000380" iyz="0.00000422" izz="0.000463"/>
    </inertial>
  </link>
  <gazebo reference="Cricket/L2_J1_shoulder1/INPUT_INTERFACE">
    <material>Gazebo/Red</material>
  </gazebo>
  <link name="HEBI_SIM/Cricket/L2_J1_shoulder1/X8_16">
    <visual>
      <origin rpy="0 0 0" xyz="-0.03 0 0.02"/>
      <geometry>
        <sphere radius="0.001"/>
      </geometry>
    </visual>
    <inertial>
      <mass value="0.001"/>
      <origin rpy="0 0 0" xyz="0 0 0"/>
      <inertia ixx="0.000001" ixy="0" ixz="0" iyy="0.000001" iyz="0" izz="0.000001"/>
    </inertial>
  </link>
  <joint name="HEBI_SIM_JOINT/Cricket/L2_J1_shoulder1" type="fixed">
    <parent link="Cricket/L2_J1_shoulder1/INPUT_INTERFACE"/>
    <child link="HEBI_SIM/Cricket/L2_J1_shoulder1/X8_16"/>
    <origin rpy="0 0 0" xyz="0 0 0"/>
  </joint>
  <gazebo reference="HEBI_SIM_JOINT/Cricket/L2_J1_shoulder1">
    <disableFixedJointLumping>true</disableFixedJointLumping>
    <preserveFixedJoint>true</preserveFixedJoint>
  </gazebo>
  <joint name="Cricket/L2_J1_shoulder1" type="continuous">
    <parent link="Cricket/L2_J1_shoulder1/INPUT_INTERFACE"/>
    <child link="leg_2_shoulder1_shoulder2/INPUT_INTERFACE"/>
    <origin rpy="0 0 0" xyz="0 0 0.045"/>
    <axis xyz="0 0 1"/>
    <limit effort="38" velocity="1.571"/>
    <dynamics damping="0.5" friction="0.5"/>
  </joint>
  <link name="leg_2_shoulder1_shoulder2/INPUT_INTERFACE">
    <visual>
      <origin rpy="1.57079632679 0 -1.57079632679" xyz="0 0 0.005"/>
      <geometry>
        <mesh filename="package://hebi_description/meshes/PM-2149-01.stl" scale="0.001 0.001 0.001"/>
      </geometry>
      <material name="black">
        <color rgba="0.1 0.1 0.1 1"/>
      </material>
    </visual>
    <visual>
      <origin rpy="1.57079632679 0 0" xyz="0 .03 .04"/>
      <geometry>
        <mesh filename="package://hebi_description/meshes/PM-2150-01R.stl" scale="0.001 0.001 0.001"/>
      </geometry>
      <material name="black">
        <color rgba="0.1 0.1 0.1 1"/>
      </material>
    </visual>
    <collision>
      <origin rpy="1.57079632679 0 -1.57079632679" xyz="0 0 0.005"/>
      <geometry>
        <mesh filename="package://hebi_description/meshes/PM-2149-01.stl" scale="0.001 0.001 0.001"/>
      </geometry>
    </collision>
    <collision>
      <origin rpy="1.57079632679 0 0" xyz="0 .03 .04"/>
      <geometry>
        <mesh filename="package://hebi_description/meshes/PM-2150-01R.stl" scale="0.001 0.001 0.001"/>
      </geometry>
    </collision>
    <!-- NOTE: inertia is just modelled as small sphere, and could be improved. -->
    <inertial>
      <origin rpy="0 0 0" xyz="0 0.01125 .0275"/>
      <mass value="0.215"/>
      <inertia ixx="0.0003096" ixy="0.0" ixz="0.0" iyy="0.0003096" iyz="0.0" izz="0.0003096"/>
    </inertial>
  </link>
  <gazebo reference="leg_2_shoulder1_shoulder2/INPUT_INTERFACE">
    <material>Gazebo/Black</material>
  </gazebo>
  <joint name="leg_2_shoulder1_shoulder2/OUTPUT_INTERFACE" type="fixed">
    <parent link="leg_2_shoulder1_shoulder2/INPUT_INTERFACE"/>
    <child link="Cricket/L2_J2_shoulder2/INPUT_INTERFACE"/>
    <origin rpy="1.57079632679 0 0" xyz="0 .0225 .055"/>
  </joint>
  <gazebo reference="leg_2_shoulder1_shoulder2/OUTPUT_INTERFACE">
    <disableFixedJointLumping>true</disableFixedJointLumping>
    <preserveFixedJoint>true</preserveFixedJoint>
  </gazebo>
  <link name="Cricket/L2_J2_shoulder2/INPUT_INTERFACE">
    <visual>
      <origin rpy="0 0 0" xyz="0 0 0"/>
      <geometry>
        <mesh filename="package://hebi_description/meshes/X8.stl" scale="0.001 0.001 0.001"/>
      </geometry>
      <material name="red">
        <color rgba=".82 0.06 0.06 1"/>
      </material>
    </visual>
    <collision>
      <origin rpy="0 0 0" xyz="0 0 0"/>
      <geometry>
        <mesh filename="package://hebi_description/meshes/X8.stl" scale="0.001 0.001 0.001"/>
      </geometry>
    </collision>
    <inertial>
      <mass value="0.5"/>
      <origin rpy="0 0 0" xyz="-0.0145 -0.0031 0.0242"/>
      <inertia ixx="0.000246" ixy="0.0000444" ixz="0.0000266" iyy="0.000380" iyz="0.00000422" izz="0.000463"/>
    </inertial>
  </link>
  <gazebo reference="Cricket/L2_J2_shoulder2/INPUT_INTERFACE">
    <material>Gazebo/Red</material>
  </gazebo>
  <link name="HEBI_SIM/Cricket/L2_J2_shoulder2/X8_16">
    <visual>
      <origin rpy="0 0 0" xyz="-0.03 0 0.02"/>
      <geometry>
        <sphere radius="0.001"/>
      </geometry>
    </visual>
    <inertial>
      <mass value="0.001"/>
      <origin rpy="0 0 0" xyz="0 0 0"/>
      <inertia ixx="0.000001" ixy="0" ixz="0" iyy="0.000001" iyz="0" izz="0.000001"/>
    </inertial>
  </link>
  <joint name="HEBI_SIM_JOINT/Cricket/L2_J2_shoulder2" type="fixed">
    <parent link="Cricket/L2_J2_shoulder2/INPUT_INTERFACE"/>
    <child link="HEBI_SIM/Cricket/L2_J2_shoulder2/X8_16"/>
    <origin rpy="0 0 0" xyz="0 0 0"/>
  </joint>
  <gazebo reference="HEBI_SIM_JOINT/Cricket/L2_J2_shoulder2">
    <disableFixedJointLumping>true</disableFixedJointLumping>
    <preserveFixedJoint>true</preserveFixedJoint>
  </gazebo>
  <joint name="Cricket/L2_J2_shoulder2" type="continuous">
    <parent link="Cricket/L2_J2_shoulder2/INPUT_INTERFACE"/>
    <child link="leg_2_knee_to_link_spacer/INPUT_INTERFACE"/>
    <origin rpy="0 0 0" xyz="0 0 0.045"/>
    <axis xyz="0 0 1"/>
    <limit effort="38" velocity="1.571"/>
    <dynamics damping="0.5" friction="0.5"/>
  </joint>
  <link name="leg_2_knee_to_link_spacer/INPUT_INTERFACE">
    <visual>
      <origin rpy="0 0 0" xyz="0.0 0.0 0.01"/>
      <geometry>
        <box size="0.05 0.05 0.02"/>
      </geometry>
      <material name="beige">
        <color rgba="0.96 0.945 0.871 1"/>
      </material>
    </visual>
    <inertial>
      <mass value="0.05"/>
      <origin rpy="0 0 0" xyz="0 0 0"/>
      <inertia ixx="0.001" ixy="0" ixz="0" iyy="0.001" iyz="0" izz="0.001"/>
    </inertial>
  </link>
  <joint name="leg_2_knee_to_link_spacer_child_joint" type="fixed">
    <origin rpy="0 0 0" xyz="0.0 0.0 0.02"/>
    <parent link="leg_2_knee_to_link_spacer/INPUT_INTERFACE"/>
    <child link="leg_2_shoulder2_knee/INPUT_INTERFACE"/>
  </joint>
  <link name="leg_2_shoulder2_knee/INPUT_INTERFACE">
    <!-- Input Cap -->
    <visual>
      <origin rpy="0 0 0" xyz="0 0 0"/>
      <geometry>
        <mesh filename="package://hebi_description/meshes/A-2038-02.stl"/>
      </geometry>
      <material name="black">
        <color rgba="0.1 0.1 0.1 1"/>
      </material>
    </visual>
    <collision>
      <origin rpy="0 0 0" xyz="0 0 0"/>
      <geometry>
        <mesh filename="package://hebi_description/meshes/A-2038-02.stl"/>
      </geometry>
    </collision>
    <!-- Link Pipe -->
    <visual>
      <origin rpy="0 1.57075 0" xyz="0.075 0 0.02"/>
      <geometry>
        <cylinder length="0.1246" radius=".016"/>
      </geometry>
      <material name="black">
        <color rgba="0.1 0.1 0.1 1"/>
      </material>
    </visual>
    <collision>
      <origin rpy="0 1.57075 0" xyz="0.075 0 0.02"/>
      <geometry>
        <cylinder length="0.1246" radius=".016"/>
      </geometry>
    </collision>
    <!-- Output Cap -->
    <visual>
      <origin rpy="0 0 0" xyz="0.15 0.0 0.04"/>
      <geometry>
        <mesh filename="package://hebi_description/meshes/A-2039-02.stl"/>
      </geometry>
      <material name="black">
        <color rgba="0.1 0.1 0.1 1"/>
      </material>
    </visual>
    <collision>
      <origin rpy="0 0 0" xyz="0.15 0.0 0.04"/>
      <geometry>
        <mesh filename="package://hebi_description/meshes/A-2039-02.stl"/>
      </geometry>
    </collision>
    <!-- Approximate inertia as thin rod about x axis -->
    <inertial>
      <origin rpy="0 0 0" xyz="0.075 0 0.02"/>
      <mass value="0.332"/>
      <inertia ixx="0.0" ixy="0.0" ixz="0.0" iyy="0.0006225" iyz="0.0" izz="0.0006225"/>
    </inertial>
  </link>
  <gazebo reference="leg_2_shoulder2_knee/INPUT_INTERFACE">
    <material>Gazebo/Black</material>
  </gazebo>
  <joint name="leg_2_shoulder2_knee/OUTPUT_JOINT" type="fixed">
    <parent link="leg_2_shoulder2_knee/INPUT_INTERFACE"/>
    <child link="Cricket/L2_J3_knee/INPUT_INTERFACE"/>
    <origin rpy="0 0 0" xyz="0.15 -0.0 0.04"/>
  </joint>
  <gazebo reference="leg_2_shoulder2_knee/OUTPUT_JOINT">
    <disableFixedJointLumping>true</disableFixedJointLumping>
    <preserveFixedJoint>true</preserveFixedJoint>
  </gazebo>
  <link name="Cricket/L2_J3_knee/INPUT_INTERFACE">
    <visual>
      <origin rpy="0 0 0" xyz="0 0 0"/>
      <geometry>
        <mesh filename="package://hebi_description/meshes/X8.stl" scale="0.001 0.001 0.001"/>
      </geometry>
      <material name="red">
        <color rgba=".82 0.06 0.06 1"/>
      </material>
    </visual>
    <collision>
      <origin rpy="0 0 0" xyz="0 0 0"/>
      <geometry>
        <mesh filename="package://hebi_description/meshes/X8.stl" scale="0.001 0.001 0.001"/>
      </geometry>
    </collision>
    <inertial>
      <mass value="0.5"/>
      <origin rpy="0 0 0" xyz="-0.0145 -0.0031 0.0242"/>
      <inertia ixx="0.000246" ixy="0.0000444" ixz="0.0000266" iyy="0.000380" iyz="0.00000422" izz="0.000463"/>
    </inertial>
  </link>
  <gazebo reference="Cricket/L2_J3_knee/INPUT_INTERFACE">
    <material>Gazebo/Red</material>
  </gazebo>
  <link name="HEBI_SIM/Cricket/L2_J3_knee/X8_16">
    <visual>
      <origin rpy="0 0 0" xyz="-0.03 0 0.02"/>
      <geometry>
        <sphere radius="0.001"/>
      </geometry>
    </visual>
    <inertial>
      <mass value="0.001"/>
      <origin rpy="0 0 0" xyz="0 0 0"/>
      <inertia ixx="0.000001" ixy="0" ixz="0" iyy="0.000001" iyz="0" izz="0.000001"/>
    </inertial>
  </link>
  <joint name="HEBI_SIM_JOINT/Cricket/L2_J3_knee" type="fixed">
    <parent link="Cricket/L2_J3_knee/INPUT_INTERFACE"/>
    <child link="HEBI_SIM/Cricket/L2_J3_knee/X8_16"/>
    <origin rpy="0 0 0" xyz="0 0 0"/>
  </joint>
  <gazebo reference="HEBI_SIM_JOINT/Cricket/L2_J3_knee">
    <disableFixedJointLumping>true</disableFixedJointLumping>
    <preserveFixedJoint>true</preserveFixedJoint>
  </gazebo>
  <joint name="Cricket/L2_J3_knee" type="continuous">
    <parent link="Cricket/L2_J3_knee/INPUT_INTERFACE"/>
    <child link="leg2_knee_ankle/INPUT_INTERFACE"/>
    <origin rpy="0 0 0" xyz="0 0 0.045"/>
    <axis xyz="0 0 1"/>
    <limit effort="38" velocity="1.571"/>
    <dynamics damping="0.5" friction="0.5"/>
  </joint>
  <link name="leg2_knee_ankle/INPUT_INTERFACE">
    <!-- Input Cap -->
    <visual>
      <origin rpy="0 0 0" xyz="0 0 0"/>
      <geometry>
        <mesh filename="package://hebi_description/meshes/A-2038-02.stl"/>
      </geometry>
      <material name="black">
        <color rgba="0.1 0.1 0.1 1"/>
      </material>
    </visual>
    <collision>
      <origin rpy="0 0 0" xyz="0 0 0"/>
      <geometry>
        <mesh filename="package://hebi_description/meshes/A-2038-02.stl"/>
      </geometry>
    </collision>
    <!-- Link Pipe -->
    <visual>
      <origin rpy="0 1.57075 0" xyz="0.1375 0 0.02"/>
      <geometry>
        <cylinder length="0.2496" radius=".016"/>
      </geometry>
      <material name="black">
        <color rgba="0.1 0.1 0.1 1"/>
      </material>
    </visual>
    <collision>
      <origin rpy="0 1.57075 0" xyz="0.1375 0 0.02"/>
      <geometry>
        <cylinder length="0.2496" radius=".016"/>
      </geometry>
    </collision>
    <!-- Output Cap -->
    <visual>
      <origin rpy="0 0 0" xyz="0.275 0.0 0.04"/>
      <geometry>
        <mesh filename="package://hebi_description/meshes/A-2039-02.stl"/>
      </geometry>
      <material name="black">
        <color rgba="0.1 0.1 0.1 1"/>
      </material>
    </visual>
    <collision>
      <origin rpy="0 0 0" xyz="0.275 0.0 0.04"/>
      <geometry>
        <mesh filename="package://hebi_description/meshes/A-2039-02.stl"/>
      </geometry>
    </collision>
    <!-- Approximate inertia as thin rod about x axis -->
    <inertial>
      <origin rpy="0 0 0" xyz="0.1375 0 0.02"/>
      <mass value="0.382"/>
      <inertia ixx="0.0" ixy="0.0" ixz="0.0" iyy="0.00240739583333" iyz="0.0" izz="0.00240739583333"/>
    </inertial>
  </link>
  <gazebo reference="leg2_knee_ankle/INPUT_INTERFACE">
    <material>Gazebo/Black</material>
  </gazebo>
  <joint name="leg2_knee_ankle/OUTPUT_JOINT" type="fixed">
    <parent link="leg2_knee_ankle/INPUT_INTERFACE"/>
    <child link="leg2_ankle_spacer/INPUT_INTERFACE"/>
    <origin rpy="0 0 0" xyz="0.275 -0.0 0.04"/>
  </joint>
  <gazebo reference="leg2_knee_ankle/OUTPUT_JOINT">
    <disableFixedJointLumping>true</disableFixedJointLumping>
    <preserveFixedJoint>true</preserveFixedJoint>
  </gazebo>
  <link name="leg2_ankle_spacer/INPUT_INTERFACE">
    <inertial>
      <mass value="0.01"/>
      <origin rpy="0 0 0" xyz="0 0 0"/>
      <inertia ixx="0.001" ixy="0" ixz="0" iyy="0.001" iyz="0" izz="0.001"/>
    </inertial>
  </link>
  <link name="Cricket/L2_J4_ankle/INPUT_INTERFACE">
    <visual>
      <origin rpy="0 0 0" xyz="0 0 0"/>
      <geometry>
        <mesh filename="package://hebi_description/meshes/X8.stl" scale="0.001 0.001 0.001"/>
      </geometry>
      <material name="red">
        <color rgba=".82 0.06 0.06 1"/>
      </material>
    </visual>
    <collision>
      <origin rpy="0 0 0" xyz="0 0 0"/>
      <geometry>
        <mesh filename="package://hebi_description/meshes/X8.stl" scale="0.001 0.001 0.001"/>
      </geometry>
    </collision>
    <inertial>
      <mass value="0.5"/>
      <origin rpy="0 0 0" xyz="-0.0145 -0.0031 0.0242"/>
      <inertia ixx="0.000246" ixy="0.0000444" ixz="0.0000266" iyy="0.000380" iyz="0.00000422" izz="0.000463"/>
    </inertial>
  </link>
  <gazebo reference="Cricket/L2_J4_ankle/INPUT_INTERFACE">
    <material>Gazebo/Red</material>
  </gazebo>
  <link name="HEBI_SIM/Cricket/L2_J4_ankle/X8_16">
    <visual>
      <origin rpy="0 0 0" xyz="-0.03 0 0.02"/>
      <geometry>
        <sphere radius="0.001"/>
      </geometry>
    </visual>
    <inertial>
      <mass value="0.001"/>
      <origin rpy="0 0 0" xyz="0 0 0"/>
      <inertia ixx="0.000001" ixy="0" ixz="0" iyy="0.000001" iyz="0" izz="0.000001"/>
    </inertial>
  </link>
  <joint name="HEBI_SIM_JOINT/Cricket/L2_J4_ankle" type="fixed">
    <parent link="Cricket/L2_J4_ankle/INPUT_INTERFACE"/>
    <child link="HEBI_SIM/Cricket/L2_J4_ankle/X8_16"/>
    <origin rpy="0 0 0" xyz="0 0 0"/>
  </joint>
  <gazebo reference="HEBI_SIM_JOINT/Cricket/L2_J4_ankle">
    <disableFixedJointLumping>true</disableFixedJointLumping>
    <preserveFixedJoint>true</preserveFixedJoint>
  </gazebo>
  <joint name="Cricket/L2_J4_ankle" type="continuous">
    <parent link="leg2_ankle_spacer/INPUT_INTERFACE"/>
    <child link="Cricket/L2_J4_ankle/INPUT_INTERFACE"/>
    <origin rpy="0 3.14159265359 0" xyz="0 0 0.045"/>
    <axis xyz="0 0 1"/>
    <limit effort="38" velocity="1.571"/>
    <dynamics damping="0.5" friction="0.5"/>
  </joint>
  <joint name="Cricket/L2_J4_ankle_fixed" type="fixed">
    <parent link="Cricket/L2_J4_ankle/INPUT_INTERFACE"/>
    <child link="leg2_track_bracket_1/INPUT_INTERFACE"/>
    <origin rpy="0 0 0" xyz="0 0 0"/>
  </joint>
  <link name="leg2_track_bracket_1/INPUT_INTERFACE">
    <visual>
      <origin rpy="0 0 0" xyz="-0.0685 0.0 -0.005"/>
      <geometry>
        <box size="0.15 0.05 0.01"/>
      </geometry>
      <material name="beige">
        <color rgba="0.96 0.945 0.871 1"/>
      </material>
    </visual>
    <inertial>
      <mass value="0.3"/>
      <origin rpy="0 0 0" xyz="0 0 0"/>
      <inertia ixx="0.001" ixy="0" ixz="0" iyy="0.001" iyz="0" izz="0.001"/>
    </inertial>
  </link>
  <joint name="leg2_track_bracket_1_child_joint" type="fixed">
    <origin rpy="0 0 0" xyz="-0.137 0.0 -0.01"/>
    <parent link="leg2_track_bracket_1/INPUT_INTERFACE"/>
    <child link="leg2_track_bracket_2/INPUT_INTERFACE"/>
  </joint>
  <link name="leg2_track_bracket_2/INPUT_INTERFACE">
    <visual>
      <origin rpy="0 0 0" xyz="0.0 0.0 0.025"/>
      <geometry>
        <box size="0.08 0.05 0.05"/>
      </geometry>
      <material name="beige">
        <color rgba="0.96 0.945 0.871 1"/>
      </material>
    </visual>
    <inertial>
      <mass value="0.3"/>
      <origin rpy="0 0 0" xyz="0 0 0"/>
      <inertia ixx="0.001" ixy="0" ixz="0" iyy="0.001" iyz="0" izz="0.001"/>
    </inertial>
  </link>
  <joint name="leg2_track_bracket_2_child_joint" type="fixed">
    <origin rpy="0 0 0" xyz="0.0 0.0 0.05"/>
    <parent link="leg2_track_bracket_2/INPUT_INTERFACE"/>
    <child link="leg2_track_bracket_3/INPUT_INTERFACE"/>
  </joint>
  <link name="leg2_track_bracket_3/INPUT_INTERFACE">
    <visual>
      <origin rpy="0 0 0" xyz="-0.0685 0.0 -0.005"/>
      <geometry>
        <box size="0.15 0.05 0.01"/>
      </geometry>
      <material name="beige">
        <color rgba="0.96 0.945 0.871 1"/>
      </material>
    </visual>
    <inertial>
      <mass value="0.3"/>
      <origin rpy="0 0 0" xyz="0 0 0"/>
      <inertia ixx="0.001" ixy="0" ixz="0" iyy="0.001" iyz="0" izz="0.001"/>
    </inertial>
  </link>
  <joint name="leg2_track_bracket_3_child_joint" type="fixed">
    <origin rpy="0 3.14159265359 0" xyz="-0.137 0.0 -0.01"/>
    <parent link="leg2_track_bracket_3/INPUT_INTERFACE"/>
    <child link="Cricket/L2_J5_track/INPUT_INTERFACE"/>
  </joint>
  <link name="Cricket/L2_J5_track/INPUT_INTERFACE">
    <visual>
      <origin rpy="0 0 0" xyz="0 0 0"/>
      <geometry>
        <mesh filename="package://hebi_description/meshes/X8.stl" scale="0.001 0.001 0.001"/>
      </geometry>
      <material name="red">
        <color rgba=".82 0.06 0.06 1"/>
      </material>
    </visual>
    <collision>
      <origin rpy="0 0 0" xyz="0 0 0"/>
      <geometry>
        <mesh filename="package://hebi_description/meshes/X8.stl" scale="0.001 0.001 0.001"/>
      </geometry>
    </collision>
    <inertial>
      <mass value="0.5"/>
      <origin rpy="0 0 0" xyz="-0.0145 -0.0031 0.0242"/>
      <inertia ixx="0.000246" ixy="0.0000444" ixz="0.0000266" iyy="0.000380" iyz="0.00000422" izz="0.000463"/>
    </inertial>
  </link>
  <gazebo reference="Cricket/L2_J5_track/INPUT_INTERFACE">
    <material>Gazebo/Red</material>
  </gazebo>
  <link name="HEBI_SIM/Cricket/L2_J5_track/X8_16">
    <visual>
      <origin rpy="0 0 0" xyz="-0.03 0 0.02"/>
      <geometry>
        <sphere radius="0.001"/>
      </geometry>
    </visual>
    <inertial>
      <mass value="0.001"/>
      <origin rpy="0 0 0" xyz="0 0 0"/>
      <inertia ixx="0.000001" ixy="0" ixz="0" iyy="0.000001" iyz="0" izz="0.000001"/>
    </inertial>
  </link>
  <joint name="HEBI_SIM_JOINT/Cricket/L2_J5_track" type="fixed">
    <parent link="Cricket/L2_J5_track/INPUT_INTERFACE"/>
    <child link="HEBI_SIM/Cricket/L2_J5_track/X8_16"/>
    <origin rpy="0 0 0" xyz="0 0 0"/>
  </joint>
  <gazebo reference="HEBI_SIM_JOINT/Cricket/L2_J5_track">
    <disableFixedJointLumping>true</disableFixedJointLumping>
    <preserveFixedJoint>true</preserveFixedJoint>
  </gazebo>
  <joint name="Cricket/L2_J5_track" type="continuous">
    <parent link="Cricket/L2_J5_track/INPUT_INTERFACE"/>
    <child link="leg2_drive_pulley/INPUT_INTERFACE"/>
    <origin rpy="0 0 0" xyz="0 0 0.045"/>
    <axis xyz="0 0 1"/>
    <limit effort="38" velocity="1.571"/>
    <dynamics damping="0.5" friction="0.5"/>
  </joint>
  <link name="leg2_drive_pulley/INPUT_INTERFACE">
    <visual>
      <origin rpy="0 0 0" xyz="0 0 0.020"/>
      <geometry>
        <cylinder length="0.033" radius="0.068"/>
      </geometry>
      <material name="black">
        <color rgba="0.1 0.1 0.1 1"/>
      </material>
    </visual>
    <collision>
      <origin rpy="0 0 0" xyz="0 0 0.020"/>
      <geometry>
        <cylinder length="0.033" radius="0.068"/>
      </geometry>
    </collision>
    <inertial>
      <mass value="0.1"/>
      <origin rpy="0 0 0" xyz="0 0 0"/>
      <inertia ixx="0.001" ixy="0" ixz="0" iyy="0.001" iyz="0" izz="0.001"/>
    </inertial>
  </link>
  <link name="leg2_idle_pulley">
    <visual>
      <origin rpy="0 0 0" xyz="0.0 0.0 -0.03"/>
      <geometry>
        <cylinder length="0.033" radius="0.068"/>
      </geometry>
      <material name="black">
        <color rgba="0.1 0.1 0.1 1"/>
      </material>
    </visual>
    <inertial>
      <mass value="0.1"/>
      <origin rpy="0 0 0" xyz="0 0 0"/>
      <inertia ixx="0.001" ixy="0" ixz="0" iyy="0.001" iyz="0" izz="0.001"/>
    </inertial>
  </link>
  <joint name="leg2_idle_pulley_joint" type="continuous">
    <origin rpy="0 0 0" xyz="0 0 0"/>
    <parent link="Cricket/L2_J4_ankle/INPUT_INTERFACE"/>
    <child link="leg2_idle_pulley"/>
    <axis xyz="0 0 1"/>
  </joint>
  <joint name="base_leg3_joint" type="fixed">
    <origin rpy="1.57079632679 0 3.14159265359" xyz="-0.135 0.100 0.030"/>
    <parent link="cricket_base"/>
    <child link="leg3_base_bracket/INPUT_INTERFACE"/>
  </joint>
  <link name="leg3_base_bracket/INPUT_INTERFACE">
    <visual>
      <origin rpy="0 0 0" xyz="0.0 0.0 0.01"/>
      <geometry>
        <box size="0.05 0.05 0.02"/>
      </geometry>
      <material name="beige">
        <color rgba="0.96 0.945 0.871 1"/>
      </material>
    </visual>
    <inertial>
      <mass value="0.05"/>
      <origin rpy="0 0 0" xyz="0 0 0"/>
      <inertia ixx="0.001" ixy="0" ixz="0" iyy="0.001" iyz="0" izz="0.001"/>
    </inertial>
  </link>
  <joint name="leg3_base_bracket_child_joint" type="fixed">
    <origin rpy="0 0 0" xyz="0.0 0.0 0.02"/>
    <parent link="leg3_base_bracket/INPUT_INTERFACE"/>
    <child link="leg3_base_shoulder1/INPUT_INTERFACE"/>
  </joint>
  <link name="leg3_base_shoulder1/INPUT_INTERFACE">
    <!-- Input Cap -->
    <visual>
      <origin rpy="0 0 0" xyz="0 0 0"/>
      <geometry>
        <mesh filename="package://hebi_description/meshes/A-2038-02.stl"/>
      </geometry>
      <material name="black">
        <color rgba="0.1 0.1 0.1 1"/>
      </material>
    </visual>
    <collision>
      <origin rpy="0 0 0" xyz="0 0 0"/>
      <geometry>
        <mesh filename="package://hebi_description/meshes/A-2038-02.stl"/>
      </geometry>
    </collision>
    <!-- Link Pipe -->
    <visual>
      <origin rpy="0 1.57075 0" xyz="0.0375 0 0.02"/>
      <geometry>
        <cylinder length="0.0496" radius=".016"/>
      </geometry>
      <material name="black">
        <color rgba="0.1 0.1 0.1 1"/>
      </material>
    </visual>
    <collision>
      <origin rpy="0 1.57075 0" xyz="0.0375 0 0.02"/>
      <geometry>
        <cylinder length="0.0496" radius=".016"/>
      </geometry>
    </collision>
    <!-- Output Cap -->
    <visual>
      <origin rpy="1.57079632679 4.71238898038 1.57079632679" xyz="0.075 0 0.02"/>
      <geometry>
        <mesh filename="package://hebi_description/meshes/A-2226-01.stl" scale="0.001 0.001 0.001"/>
      </geometry>
      <material name="black">
        <color rgba="0.1 0.1 0.1 1"/>
      </material>
    </visual>
    <collision>
      <origin rpy="1.57079632679 4.71238898038 1.57079632679" xyz="0.075 0 0.02"/>
      <geometry>
        <mesh filename="package://hebi_description/meshes/A-2039-02.stl"/>
      </geometry>
    </collision>
    <!-- Approximate inertia as thin rod about x axis -->
    <inertial>
      <origin rpy="0 0 0" xyz="0.0375 0 0.02"/>
      <mass value="0.302"/>
      <inertia ixx="0.0" ixy="0.0" ixz="0.0" iyy="0.0001415625" iyz="0.0" izz="0.0001415625"/>
    </inertial>
  </link>
  <gazebo reference="leg3_base_shoulder1/INPUT_INTERFACE">
    <material>Gazebo/Black</material>
  </gazebo>
  <joint name="leg3_base_shoulder1/OUTPUT_JOINT" type="fixed">
    <parent link="leg3_base_shoulder1/INPUT_INTERFACE"/>
    <child link="Cricket/L3_J1_shoulder1/INPUT_INTERFACE"/>
    <origin rpy="1.57079632679 4.71238898038 1.57079632679" xyz="0.075 0 0.02"/>
  </joint>
  <gazebo reference="leg3_base_shoulder1/OUTPUT_JOINT">
    <disableFixedJointLumping>true</disableFixedJointLumping>
    <preserveFixedJoint>true</preserveFixedJoint>
  </gazebo>
  <link name="Cricket/L3_J1_shoulder1/INPUT_INTERFACE">
    <visual>
      <origin rpy="0 0 0" xyz="0 0 0"/>
      <geometry>
        <mesh filename="package://hebi_description/meshes/X8.stl" scale="0.001 0.001 0.001"/>
      </geometry>
      <material name="red">
        <color rgba=".82 0.06 0.06 1"/>
      </material>
    </visual>
    <collision>
      <origin rpy="0 0 0" xyz="0 0 0"/>
      <geometry>
        <mesh filename="package://hebi_description/meshes/X8.stl" scale="0.001 0.001 0.001"/>
      </geometry>
    </collision>
    <inertial>
      <mass value="0.5"/>
      <origin rpy="0 0 0" xyz="-0.0145 -0.0031 0.0242"/>
      <inertia ixx="0.000246" ixy="0.0000444" ixz="0.0000266" iyy="0.000380" iyz="0.00000422" izz="0.000463"/>
    </inertial>
  </link>
  <gazebo reference="Cricket/L3_J1_shoulder1/INPUT_INTERFACE">
    <material>Gazebo/Red</material>
  </gazebo>
  <link name="HEBI_SIM/Cricket/L3_J1_shoulder1/X8_16">
    <visual>
      <origin rpy="0 0 0" xyz="-0.03 0 0.02"/>
      <geometry>
        <sphere radius="0.001"/>
      </geometry>
    </visual>
    <inertial>
      <mass value="0.001"/>
      <origin rpy="0 0 0" xyz="0 0 0"/>
      <inertia ixx="0.000001" ixy="0" ixz="0" iyy="0.000001" iyz="0" izz="0.000001"/>
    </inertial>
  </link>
  <joint name="HEBI_SIM_JOINT/Cricket/L3_J1_shoulder1" type="fixed">
    <parent link="Cricket/L3_J1_shoulder1/INPUT_INTERFACE"/>
    <child link="HEBI_SIM/Cricket/L3_J1_shoulder1/X8_16"/>
    <origin rpy="0 0 0" xyz="0 0 0"/>
  </joint>
  <gazebo reference="HEBI_SIM_JOINT/Cricket/L3_J1_shoulder1">
    <disableFixedJointLumping>true</disableFixedJointLumping>
    <preserveFixedJoint>true</preserveFixedJoint>
  </gazebo>
  <joint name="Cricket/L3_J1_shoulder1" type="continuous">
    <parent link="Cricket/L3_J1_shoulder1/INPUT_INTERFACE"/>
    <child link="leg_3_shoulder1_shoulder2/INPUT_INTERFACE"/>
    <origin rpy="0 0 0" xyz="0 0 0.045"/>
    <axis xyz="0 0 1"/>
    <limit effort="38" velocity="1.571"/>
    <dynamics damping="0.5" friction="0.5"/>
  </joint>
  <link name="leg_3_shoulder1_shoulder2/INPUT_INTERFACE">
    <visual>
      <origin rpy="1.57079632679 0 -1.57079632679" xyz="0 0 0.005"/>
      <geometry>
        <mesh filename="package://hebi_description/meshes/PM-2149-01.stl" scale="0.001 0.001 0.001"/>
      </geometry>
      <material name="black">
        <color rgba="0.1 0.1 0.1 1"/>
      </material>
    </visual>
    <visual>
      <origin rpy="1.57079632679 0 0" xyz="0 .03 .04"/>
      <geometry>
        <mesh filename="package://hebi_description/meshes/PM-2150-01R.stl" scale="0.001 0.001 0.001"/>
      </geometry>
      <material name="black">
        <color rgba="0.1 0.1 0.1 1"/>
      </material>
    </visual>
    <collision>
      <origin rpy="1.57079632679 0 -1.57079632679" xyz="0 0 0.005"/>
      <geometry>
        <mesh filename="package://hebi_description/meshes/PM-2149-01.stl" scale="0.001 0.001 0.001"/>
      </geometry>
    </collision>
    <collision>
      <origin rpy="1.57079632679 0 0" xyz="0 .03 .04"/>
      <geometry>
        <mesh filename="package://hebi_description/meshes/PM-2150-01R.stl" scale="0.001 0.001 0.001"/>
      </geometry>
    </collision>
    <!-- NOTE: inertia is just modelled as small sphere, and could be improved. -->
    <inertial>
      <origin rpy="0 0 0" xyz="0 0.01125 .0275"/>
      <mass value="0.215"/>
      <inertia ixx="0.0003096" ixy="0.0" ixz="0.0" iyy="0.0003096" iyz="0.0" izz="0.0003096"/>
    </inertial>
  </link>
  <gazebo reference="leg_3_shoulder1_shoulder2/INPUT_INTERFACE">
    <material>Gazebo/Black</material>
  </gazebo>
  <joint name="leg_3_shoulder1_shoulder2/OUTPUT_INTERFACE" type="fixed">
    <parent link="leg_3_shoulder1_shoulder2/INPUT_INTERFACE"/>
    <child link="Cricket/L3_J2_shoulder2/INPUT_INTERFACE"/>
    <origin rpy="1.57079632679 0 0" xyz="0 .0225 .055"/>
  </joint>
  <gazebo reference="leg_3_shoulder1_shoulder2/OUTPUT_INTERFACE">
    <disableFixedJointLumping>true</disableFixedJointLumping>
    <preserveFixedJoint>true</preserveFixedJoint>
  </gazebo>
  <link name="Cricket/L3_J2_shoulder2/INPUT_INTERFACE">
    <visual>
      <origin rpy="0 0 0" xyz="0 0 0"/>
      <geometry>
        <mesh filename="package://hebi_description/meshes/X8.stl" scale="0.001 0.001 0.001"/>
      </geometry>
      <material name="red">
        <color rgba=".82 0.06 0.06 1"/>
      </material>
    </visual>
    <collision>
      <origin rpy="0 0 0" xyz="0 0 0"/>
      <geometry>
        <mesh filename="package://hebi_description/meshes/X8.stl" scale="0.001 0.001 0.001"/>
      </geometry>
    </collision>
    <inertial>
      <mass value="0.5"/>
      <origin rpy="0 0 0" xyz="-0.0145 -0.0031 0.0242"/>
      <inertia ixx="0.000246" ixy="0.0000444" ixz="0.0000266" iyy="0.000380" iyz="0.00000422" izz="0.000463"/>
    </inertial>
  </link>
  <gazebo reference="Cricket/L3_J2_shoulder2/INPUT_INTERFACE">
    <material>Gazebo/Red</material>
  </gazebo>
  <link name="HEBI_SIM/Cricket/L3_J2_shoulder2/X8_16">
    <visual>
      <origin rpy="0 0 0" xyz="-0.03 0 0.02"/>
      <geometry>
        <sphere radius="0.001"/>
      </geometry>
    </visual>
    <inertial>
      <mass value="0.001"/>
      <origin rpy="0 0 0" xyz="0 0 0"/>
      <inertia ixx="0.000001" ixy="0" ixz="0" iyy="0.000001" iyz="0" izz="0.000001"/>
    </inertial>
  </link>
  <joint name="HEBI_SIM_JOINT/Cricket/L3_J2_shoulder2" type="fixed">
    <parent link="Cricket/L3_J2_shoulder2/INPUT_INTERFACE"/>
    <child link="HEBI_SIM/Cricket/L3_J2_shoulder2/X8_16"/>
    <origin rpy="0 0 0" xyz="0 0 0"/>
  </joint>
  <gazebo reference="HEBI_SIM_JOINT/Cricket/L3_J2_shoulder2">
    <disableFixedJointLumping>true</disableFixedJointLumping>
    <preserveFixedJoint>true</preserveFixedJoint>
  </gazebo>
  <joint name="Cricket/L3_J2_shoulder2" type="continuous">
    <parent link="Cricket/L3_J2_shoulder2/INPUT_INTERFACE"/>
    <child link="leg_3_knee_to_link_spacer/INPUT_INTERFACE"/>
    <origin rpy="0 0 0" xyz="0 0 0.045"/>
    <axis xyz="0 0 1"/>
    <limit effort="38" velocity="1.571"/>
    <dynamics damping="0.5" friction="0.5"/>
  </joint>
  <link name="leg_3_knee_to_link_spacer/INPUT_INTERFACE">
    <visual>
      <origin rpy="0 0 0" xyz="0.0 0.0 0.01"/>
      <geometry>
        <box size="0.05 0.05 0.02"/>
      </geometry>
      <material name="beige">
        <color rgba="0.96 0.945 0.871 1"/>
      </material>
    </visual>
    <inertial>
      <mass value="0.05"/>
      <origin rpy="0 0 0" xyz="0 0 0"/>
      <inertia ixx="0.001" ixy="0" ixz="0" iyy="0.001" iyz="0" izz="0.001"/>
    </inertial>
  </link>
  <joint name="leg_3_knee_to_link_spacer_child_joint" type="fixed">
    <origin rpy="0 0 0" xyz="0.0 0.0 0.02"/>
    <parent link="leg_3_knee_to_link_spacer/INPUT_INTERFACE"/>
    <child link="leg_3_shoulder2_knee/INPUT_INTERFACE"/>
  </joint>
  <link name="leg_3_shoulder2_knee/INPUT_INTERFACE">
    <!-- Input Cap -->
    <visual>
      <origin rpy="0 0 0" xyz="0 0 0"/>
      <geometry>
        <mesh filename="package://hebi_description/meshes/A-2038-02.stl"/>
      </geometry>
      <material name="black">
        <color rgba="0.1 0.1 0.1 1"/>
      </material>
    </visual>
    <collision>
      <origin rpy="0 0 0" xyz="0 0 0"/>
      <geometry>
        <mesh filename="package://hebi_description/meshes/A-2038-02.stl"/>
      </geometry>
    </collision>
    <!-- Link Pipe -->
    <visual>
      <origin rpy="0 1.57075 0" xyz="0.075 0 0.02"/>
      <geometry>
        <cylinder length="0.1246" radius=".016"/>
      </geometry>
      <material name="black">
        <color rgba="0.1 0.1 0.1 1"/>
      </material>
    </visual>
    <collision>
      <origin rpy="0 1.57075 0" xyz="0.075 0 0.02"/>
      <geometry>
        <cylinder length="0.1246" radius=".016"/>
      </geometry>
    </collision>
    <!-- Output Cap -->
    <visual>
      <origin rpy="0 0 0" xyz="0.15 0.0 0.04"/>
      <geometry>
        <mesh filename="package://hebi_description/meshes/A-2039-02.stl"/>
      </geometry>
      <material name="black">
        <color rgba="0.1 0.1 0.1 1"/>
      </material>
    </visual>
    <collision>
      <origin rpy="0 0 0" xyz="0.15 0.0 0.04"/>
      <geometry>
        <mesh filename="package://hebi_description/meshes/A-2039-02.stl"/>
      </geometry>
    </collision>
    <!-- Approximate inertia as thin rod about x axis -->
    <inertial>
      <origin rpy="0 0 0" xyz="0.075 0 0.02"/>
      <mass value="0.332"/>
      <inertia ixx="0.0" ixy="0.0" ixz="0.0" iyy="0.0006225" iyz="0.0" izz="0.0006225"/>
    </inertial>
  </link>
  <gazebo reference="leg_3_shoulder2_knee/INPUT_INTERFACE">
    <material>Gazebo/Black</material>
  </gazebo>
  <joint name="leg_3_shoulder2_knee/OUTPUT_JOINT" type="fixed">
    <parent link="leg_3_shoulder2_knee/INPUT_INTERFACE"/>
    <child link="Cricket/L3_J3_knee/INPUT_INTERFACE"/>
    <origin rpy="0 0 0" xyz="0.15 -0.0 0.04"/>
  </joint>
  <gazebo reference="leg_3_shoulder2_knee/OUTPUT_JOINT">
    <disableFixedJointLumping>true</disableFixedJointLumping>
    <preserveFixedJoint>true</preserveFixedJoint>
  </gazebo>
  <link name="Cricket/L3_J3_knee/INPUT_INTERFACE">
    <visual>
      <origin rpy="0 0 0" xyz="0 0 0"/>
      <geometry>
        <mesh filename="package://hebi_description/meshes/X8.stl" scale="0.001 0.001 0.001"/>
      </geometry>
      <material name="red">
        <color rgba=".82 0.06 0.06 1"/>
      </material>
    </visual>
    <collision>
      <origin rpy="0 0 0" xyz="0 0 0"/>
      <geometry>
        <mesh filename="package://hebi_description/meshes/X8.stl" scale="0.001 0.001 0.001"/>
      </geometry>
    </collision>
    <inertial>
      <mass value="0.5"/>
      <origin rpy="0 0 0" xyz="-0.0145 -0.0031 0.0242"/>
      <inertia ixx="0.000246" ixy="0.0000444" ixz="0.0000266" iyy="0.000380" iyz="0.00000422" izz="0.000463"/>
    </inertial>
  </link>
  <gazebo reference="Cricket/L3_J3_knee/INPUT_INTERFACE">
    <material>Gazebo/Red</material>
  </gazebo>
  <link name="HEBI_SIM/Cricket/L3_J3_knee/X8_16">
    <visual>
      <origin rpy="0 0 0" xyz="-0.03 0 0.02"/>
      <geometry>
        <sphere radius="0.001"/>
      </geometry>
    </visual>
    <inertial>
      <mass value="0.001"/>
      <origin rpy="0 0 0" xyz="0 0 0"/>
      <inertia ixx="0.000001" ixy="0" ixz="0" iyy="0.000001" iyz="0" izz="0.000001"/>
    </inertial>
  </link>
  <joint name="HEBI_SIM_JOINT/Cricket/L3_J3_knee" type="fixed">
    <parent link="Cricket/L3_J3_knee/INPUT_INTERFACE"/>
    <child link="HEBI_SIM/Cricket/L3_J3_knee/X8_16"/>
    <origin rpy="0 0 0" xyz="0 0 0"/>
  </joint>
  <gazebo reference="HEBI_SIM_JOINT/Cricket/L3_J3_knee">
    <disableFixedJointLumping>true</disableFixedJointLumping>
    <preserveFixedJoint>true</preserveFixedJoint>
  </gazebo>
  <joint name="Cricket/L3_J3_knee" type="continuous">
    <parent link="Cricket/L3_J3_knee/INPUT_INTERFACE"/>
    <child link="leg3_knee_ankle/INPUT_INTERFACE"/>
    <origin rpy="0 0 0" xyz="0 0 0.045"/>
    <axis xyz="0 0 1"/>
    <limit effort="38" velocity="1.571"/>
    <dynamics damping="0.5" friction="0.5"/>
  </joint>
  <link name="leg3_knee_ankle/INPUT_INTERFACE">
    <!-- Input Cap -->
    <visual>
      <origin rpy="0 0 0" xyz="0 0 0"/>
      <geometry>
        <mesh filename="package://hebi_description/meshes/A-2038-02.stl"/>
      </geometry>
      <material name="black">
        <color rgba="0.1 0.1 0.1 1"/>
      </material>
    </visual>
    <collision>
      <origin rpy="0 0 0" xyz="0 0 0"/>
      <geometry>
        <mesh filename="package://hebi_description/meshes/A-2038-02.stl"/>
      </geometry>
    </collision>
    <!-- Link Pipe -->
    <visual>
      <origin rpy="0 1.57075 0" xyz="0.1375 0 0.02"/>
      <geometry>
        <cylinder length="0.2496" radius=".016"/>
      </geometry>
      <material name="black">
        <color rgba="0.1 0.1 0.1 1"/>
      </material>
    </visual>
    <collision>
      <origin rpy="0 1.57075 0" xyz="0.1375 0 0.02"/>
      <geometry>
        <cylinder length="0.2496" radius=".016"/>
      </geometry>
    </collision>
    <!-- Output Cap -->
    <visual>
      <origin rpy="0 0 0" xyz="0.275 0.0 0.04"/>
      <geometry>
        <mesh filename="package://hebi_description/meshes/A-2039-02.stl"/>
      </geometry>
      <material name="black">
        <color rgba="0.1 0.1 0.1 1"/>
      </material>
    </visual>
    <collision>
      <origin rpy="0 0 0" xyz="0.275 0.0 0.04"/>
      <geometry>
        <mesh filename="package://hebi_description/meshes/A-2039-02.stl"/>
      </geometry>
    </collision>
    <!-- Approximate inertia as thin rod about x axis -->
    <inertial>
      <origin rpy="0 0 0" xyz="0.1375 0 0.02"/>
      <mass value="0.382"/>
      <inertia ixx="0.0" ixy="0.0" ixz="0.0" iyy="0.00240739583333" iyz="0.0" izz="0.00240739583333"/>
    </inertial>
  </link>
  <gazebo reference="leg3_knee_ankle/INPUT_INTERFACE">
    <material>Gazebo/Black</material>
  </gazebo>
  <joint name="leg3_knee_ankle/OUTPUT_JOINT" type="fixed">
    <parent link="leg3_knee_ankle/INPUT_INTERFACE"/>
    <child link="leg3_ankle_spacer/INPUT_INTERFACE"/>
    <origin rpy="0 0 0" xyz="0.275 -0.0 0.04"/>
  </joint>
  <gazebo reference="leg3_knee_ankle/OUTPUT_JOINT">
    <disableFixedJointLumping>true</disableFixedJointLumping>
    <preserveFixedJoint>true</preserveFixedJoint>
  </gazebo>
  <link name="leg3_ankle_spacer/INPUT_INTERFACE">
    <inertial>
      <mass value="0.01"/>
      <origin rpy="0 0 0" xyz="0 0 0"/>
      <inertia ixx="0.001" ixy="0" ixz="0" iyy="0.001" iyz="0" izz="0.001"/>
    </inertial>
  </link>
  <link name="Cricket/L3_J4_ankle/INPUT_INTERFACE">
    <visual>
      <origin rpy="0 0 0" xyz="0 0 0"/>
      <geometry>
        <mesh filename="package://hebi_description/meshes/X8.stl" scale="0.001 0.001 0.001"/>
      </geometry>
      <material name="red">
        <color rgba=".82 0.06 0.06 1"/>
      </material>
    </visual>
    <collision>
      <origin rpy="0 0 0" xyz="0 0 0"/>
      <geometry>
        <mesh filename="package://hebi_description/meshes/X8.stl" scale="0.001 0.001 0.001"/>
      </geometry>
    </collision>
    <inertial>
      <mass value="0.5"/>
      <origin rpy="0 0 0" xyz="-0.0145 -0.0031 0.0242"/>
      <inertia ixx="0.000246" ixy="0.0000444" ixz="0.0000266" iyy="0.000380" iyz="0.00000422" izz="0.000463"/>
    </inertial>
  </link>
  <gazebo reference="Cricket/L3_J4_ankle/INPUT_INTERFACE">
    <material>Gazebo/Red</material>
  </gazebo>
  <link name="HEBI_SIM/Cricket/L3_J4_ankle/X8_16">
    <visual>
      <origin rpy="0 0 0" xyz="-0.03 0 0.02"/>
      <geometry>
        <sphere radius="0.001"/>
      </geometry>
    </visual>
    <inertial>
      <mass value="0.001"/>
      <origin rpy="0 0 0" xyz="0 0 0"/>
      <inertia ixx="0.000001" ixy="0" ixz="0" iyy="0.000001" iyz="0" izz="0.000001"/>
    </inertial>
  </link>
  <joint name="HEBI_SIM_JOINT/Cricket/L3_J4_ankle" type="fixed">
    <parent link="Cricket/L3_J4_ankle/INPUT_INTERFACE"/>
    <child link="HEBI_SIM/Cricket/L3_J4_ankle/X8_16"/>
    <origin rpy="0 0 0" xyz="0 0 0"/>
  </joint>
  <gazebo reference="HEBI_SIM_JOINT/Cricket/L3_J4_ankle">
    <disableFixedJointLumping>true</disableFixedJointLumping>
    <preserveFixedJoint>true</preserveFixedJoint>
  </gazebo>
  <joint name="Cricket/L3_J4_ankle" type="continuous">
    <parent link="leg3_ankle_spacer/INPUT_INTERFACE"/>
    <child link="Cricket/L3_J4_ankle/INPUT_INTERFACE"/>
    <origin rpy="0 3.14159265359 0" xyz="0 0 0.045"/>
    <axis xyz="0 0 1"/>
    <limit effort="38" velocity="1.571"/>
    <dynamics damping="0.5" friction="0.5"/>
  </joint>
  <joint name="Cricket/L3_J4_ankle_fixed" type="fixed">
    <parent link="Cricket/L3_J4_ankle/INPUT_INTERFACE"/>
    <child link="leg3_track_bracket_1/INPUT_INTERFACE"/>
    <origin rpy="0 0 0" xyz="0 0 0"/>
  </joint>
  <link name="leg3_track_bracket_1/INPUT_INTERFACE">
    <visual>
      <origin rpy="0 0 0" xyz="-0.0685 0.0 -0.005"/>
      <geometry>
        <box size="0.15 0.05 0.01"/>
      </geometry>
      <material name="beige">
        <color rgba="0.96 0.945 0.871 1"/>
      </material>
    </visual>
    <inertial>
      <mass value="0.3"/>
      <origin rpy="0 0 0" xyz="0 0 0"/>
      <inertia ixx="0.001" ixy="0" ixz="0" iyy="0.001" iyz="0" izz="0.001"/>
    </inertial>
  </link>
  <joint name="leg3_track_bracket_1_child_joint" type="fixed">
    <origin rpy="0 0 0" xyz="-0.137 0.0 -0.01"/>
    <parent link="leg3_track_bracket_1/INPUT_INTERFACE"/>
    <child link="leg3_track_bracket_2/INPUT_INTERFACE"/>
  </joint>
  <link name="leg3_track_bracket_2/INPUT_INTERFACE">
    <visual>
      <origin rpy="0 0 0" xyz="0.0 0.0 0.025"/>
      <geometry>
        <box size="0.08 0.05 0.05"/>
      </geometry>
      <material name="beige">
        <color rgba="0.96 0.945 0.871 1"/>
      </material>
    </visual>
    <inertial>
      <mass value="0.3"/>
      <origin rpy="0 0 0" xyz="0 0 0"/>
      <inertia ixx="0.001" ixy="0" ixz="0" iyy="0.001" iyz="0" izz="0.001"/>
    </inertial>
  </link>
  <joint name="leg3_track_bracket_2_child_joint" type="fixed">
    <origin rpy="0 0 0" xyz="0.0 0.0 0.05"/>
    <parent link="leg3_track_bracket_2/INPUT_INTERFACE"/>
    <child link="leg3_track_bracket_3/INPUT_INTERFACE"/>
  </joint>
  <link name="leg3_track_bracket_3/INPUT_INTERFACE">
    <visual>
      <origin rpy="0 0 0" xyz="-0.0685 0.0 -0.005"/>
      <geometry>
        <box size="0.15 0.05 0.01"/>
      </geometry>
      <material name="beige">
        <color rgba="0.96 0.945 0.871 1"/>
      </material>
    </visual>
    <inertial>
      <mass value="0.3"/>
      <origin rpy="0 0 0" xyz="0 0 0"/>
      <inertia ixx="0.001" ixy="0" ixz="0" iyy="0.001" iyz="0" izz="0.001"/>
    </inertial>
  </link>
  <joint name="leg3_track_bracket_3_child_joint" type="fixed">
    <origin rpy="0 3.14159265359 0" xyz="-0.137 0.0 -0.01"/>
    <parent link="leg3_track_bracket_3/INPUT_INTERFACE"/>
    <child link="Cricket/L3_J5_track/INPUT_INTERFACE"/>
  </joint>
  <link name="Cricket/L3_J5_track/INPUT_INTERFACE">
    <visual>
      <origin rpy="0 0 0" xyz="0 0 0"/>
      <geometry>
        <mesh filename="package://hebi_description/meshes/X8.stl" scale="0.001 0.001 0.001"/>
      </geometry>
      <material name="red">
        <color rgba=".82 0.06 0.06 1"/>
      </material>
    </visual>
    <collision>
      <origin rpy="0 0 0" xyz="0 0 0"/>
      <geometry>
        <mesh filename="package://hebi_description/meshes/X8.stl" scale="0.001 0.001 0.001"/>
      </geometry>
    </collision>
    <inertial>
      <mass value="0.5"/>
      <origin rpy="0 0 0" xyz="-0.0145 -0.0031 0.0242"/>
      <inertia ixx="0.000246" ixy="0.0000444" ixz="0.0000266" iyy="0.000380" iyz="0.00000422" izz="0.000463"/>
    </inertial>
  </link>
  <gazebo reference="Cricket/L3_J5_track/INPUT_INTERFACE">
    <material>Gazebo/Red</material>
  </gazebo>
  <link name="HEBI_SIM/Cricket/L3_J5_track/X8_16">
    <visual>
      <origin rpy="0 0 0" xyz="-0.03 0 0.02"/>
      <geometry>
        <sphere radius="0.001"/>
      </geometry>
    </visual>
    <inertial>
      <mass value="0.001"/>
      <origin rpy="0 0 0" xyz="0 0 0"/>
      <inertia ixx="0.000001" ixy="0" ixz="0" iyy="0.000001" iyz="0" izz="0.000001"/>
    </inertial>
  </link>
  <joint name="HEBI_SIM_JOINT/Cricket/L3_J5_track" type="fixed">
    <parent link="Cricket/L3_J5_track/INPUT_INTERFACE"/>
    <child link="HEBI_SIM/Cricket/L3_J5_track/X8_16"/>
    <origin rpy="0 0 0" xyz="0 0 0"/>
  </joint>
  <gazebo reference="HEBI_SIM_JOINT/Cricket/L3_J5_track">
    <disableFixedJointLumping>true</disableFixedJointLumping>
    <preserveFixedJoint>true</preserveFixedJoint>
  </gazebo>
  <joint name="Cricket/L3_J5_track" type="continuous">
    <parent link="Cricket/L3_J5_track/INPUT_INTERFACE"/>
    <child link="leg3_drive_pulley/INPUT_INTERFACE"/>
    <origin rpy="0 0 0" xyz="0 0 0.045"/>
    <axis xyz="0 0 1"/>
    <limit effort="38" velocity="1.571"/>
    <dynamics damping="0.5" friction="0.5"/>
  </joint>
  <link name="leg3_drive_pulley/INPUT_INTERFACE">
    <visual>
      <origin rpy="0 0 0" xyz="0 0 0.020"/>
      <geometry>
        <cylinder length="0.033" radius="0.068"/>
      </geometry>
      <material name="black">
        <color rgba="0.1 0.1 0.1 1"/>
      </material>
    </visual>
    <collision>
      <origin rpy="0 0 0" xyz="0 0 0.020"/>
      <geometry>
        <cylinder length="0.033" radius="0.068"/>
      </geometry>
    </collision>
    <inertial>
      <mass value="0.1"/>
      <origin rpy="0 0 0" xyz="0 0 0"/>
      <inertia ixx="0.001" ixy="0" ixz="0" iyy="0.001" iyz="0" izz="0.001"/>
    </inertial>
  </link>
  <link name="leg3_idle_pulley">
    <visual>
      <origin rpy="0 0 0" xyz="0.0 0.0 -0.03"/>
      <geometry>
        <cylinder length="0.033" radius="0.068"/>
      </geometry>
      <material name="black">
        <color rgba="0.1 0.1 0.1 1"/>
      </material>
    </visual>
    <inertial>
      <mass value="0.1"/>
      <origin rpy="0 0 0" xyz="0 0 0"/>
      <inertia ixx="0.001" ixy="0" ixz="0" iyy="0.001" iyz="0" izz="0.001"/>
    </inertial>
  </link>
  <joint name="leg3_idle_pulley_joint" type="continuous">
    <origin rpy="0 0 0" xyz="0 0 0"/>
    <parent link="Cricket/L3_J4_ankle/INPUT_INTERFACE"/>
    <child link="leg3_idle_pulley"/>
    <axis xyz="0 0 1"/>
  </joint>
  <joint name="base_leg4_joint" type="fixed">
    <origin rpy="-1.57079632679 0 -3.14159265359" xyz="-0.135 -0.100 0.030"/>
    <parent link="cricket_base"/>
    <child link="leg4_base_bracket/INPUT_INTERFACE"/>
  </joint>
  <link name="leg4_base_bracket/INPUT_INTERFACE">
    <visual>
      <origin rpy="0 0 0" xyz="0.0 0.0 0.01"/>
      <geometry>
        <box size="0.05 0.05 0.02"/>
      </geometry>
      <material name="beige">
        <color rgba="0.96 0.945 0.871 1"/>
      </material>
    </visual>
    <inertial>
      <mass value="0.05"/>
      <origin rpy="0 0 0" xyz="0 0 0"/>
      <inertia ixx="0.001" ixy="0" ixz="0" iyy="0.001" iyz="0" izz="0.001"/>
    </inertial>
  </link>
  <joint name="leg4_base_bracket_child_joint" type="fixed">
    <origin rpy="0 0 0" xyz="0.0 0.0 0.02"/>
    <parent link="leg4_base_bracket/INPUT_INTERFACE"/>
    <child link="leg4_base_shoulder1/INPUT_INTERFACE"/>
  </joint>
  <link name="leg4_base_shoulder1/INPUT_INTERFACE">
    <!-- Input Cap -->
    <visual>
      <origin rpy="0 0 0" xyz="0 0 0"/>
      <geometry>
        <mesh filename="package://hebi_description/meshes/A-2038-02.stl"/>
      </geometry>
      <material name="black">
        <color rgba="0.1 0.1 0.1 1"/>
      </material>
    </visual>
    <collision>
      <origin rpy="0 0 0" xyz="0 0 0"/>
      <geometry>
        <mesh filename="package://hebi_description/meshes/A-2038-02.stl"/>
      </geometry>
    </collision>
    <!-- Link Pipe -->
    <visual>
      <origin rpy="0 1.57075 0" xyz="0.0375 0 0.02"/>
      <geometry>
        <cylinder length="0.0496" radius=".016"/>
      </geometry>
      <material name="black">
        <color rgba="0.1 0.1 0.1 1"/>
      </material>
    </visual>
    <collision>
      <origin rpy="0 1.57075 0" xyz="0.0375 0 0.02"/>
      <geometry>
        <cylinder length="0.0496" radius=".016"/>
      </geometry>
    </collision>
    <!-- Output Cap -->
    <visual>
      <origin rpy="1.57079632679 4.71238898038 1.57079632679" xyz="0.075 0 0.02"/>
      <geometry>
        <mesh filename="package://hebi_description/meshes/A-2226-01.stl" scale="0.001 0.001 0.001"/>
      </geometry>
      <material name="black">
        <color rgba="0.1 0.1 0.1 1"/>
      </material>
    </visual>
    <collision>
      <origin rpy="1.57079632679 4.71238898038 1.57079632679" xyz="0.075 0 0.02"/>
      <geometry>
        <mesh filename="package://hebi_description/meshes/A-2039-02.stl"/>
      </geometry>
    </collision>
    <!-- Approximate inertia as thin rod about x axis -->
    <inertial>
      <origin rpy="0 0 0" xyz="0.0375 0 0.02"/>
      <mass value="0.302"/>
      <inertia ixx="0.0" ixy="0.0" ixz="0.0" iyy="0.0001415625" iyz="0.0" izz="0.0001415625"/>
    </inertial>
  </link>
  <gazebo reference="leg4_base_shoulder1/INPUT_INTERFACE">
    <material>Gazebo/Black</material>
  </gazebo>
  <joint name="leg4_base_shoulder1/OUTPUT_JOINT" type="fixed">
    <parent link="leg4_base_shoulder1/INPUT_INTERFACE"/>
    <child link="Cricket/L4_J1_shoulder1/INPUT_INTERFACE"/>
    <origin rpy="1.57079632679 4.71238898038 1.57079632679" xyz="0.075 0 0.02"/>
  </joint>
  <gazebo reference="leg4_base_shoulder1/OUTPUT_JOINT">
    <disableFixedJointLumping>true</disableFixedJointLumping>
    <preserveFixedJoint>true</preserveFixedJoint>
  </gazebo>
  <link name="Cricket/L4_J1_shoulder1/INPUT_INTERFACE">
    <visual>
      <origin rpy="0 0 0" xyz="0 0 0"/>
      <geometry>
        <mesh filename="package://hebi_description/meshes/X8.stl" scale="0.001 0.001 0.001"/>
      </geometry>
      <material name="red">
        <color rgba=".82 0.06 0.06 1"/>
      </material>
    </visual>
    <collision>
      <origin rpy="0 0 0" xyz="0 0 0"/>
      <geometry>
        <mesh filename="package://hebi_description/meshes/X8.stl" scale="0.001 0.001 0.001"/>
      </geometry>
    </collision>
    <inertial>
      <mass value="0.5"/>
      <origin rpy="0 0 0" xyz="-0.0145 -0.0031 0.0242"/>
      <inertia ixx="0.000246" ixy="0.0000444" ixz="0.0000266" iyy="0.000380" iyz="0.00000422" izz="0.000463"/>
    </inertial>
  </link>
  <gazebo reference="Cricket/L4_J1_shoulder1/INPUT_INTERFACE">
    <material>Gazebo/Red</material>
  </gazebo>
  <link name="HEBI_SIM/Cricket/L4_J1_shoulder1/X8_16">
    <visual>
      <origin rpy="0 0 0" xyz="-0.03 0 0.02"/>
      <geometry>
        <sphere radius="0.001"/>
      </geometry>
    </visual>
    <inertial>
      <mass value="0.001"/>
      <origin rpy="0 0 0" xyz="0 0 0"/>
      <inertia ixx="0.000001" ixy="0" ixz="0" iyy="0.000001" iyz="0" izz="0.000001"/>
    </inertial>
  </link>
  <joint name="HEBI_SIM_JOINT/Cricket/L4_J1_shoulder1" type="fixed">
    <parent link="Cricket/L4_J1_shoulder1/INPUT_INTERFACE"/>
    <child link="HEBI_SIM/Cricket/L4_J1_shoulder1/X8_16"/>
    <origin rpy="0 0 0" xyz="0 0 0"/>
  </joint>
  <gazebo reference="HEBI_SIM_JOINT/Cricket/L4_J1_shoulder1">
    <disableFixedJointLumping>true</disableFixedJointLumping>
    <preserveFixedJoint>true</preserveFixedJoint>
  </gazebo>
  <joint name="Cricket/L4_J1_shoulder1" type="continuous">
    <parent link="Cricket/L4_J1_shoulder1/INPUT_INTERFACE"/>
    <child link="leg_4_shoulder1_shoulder2/INPUT_INTERFACE"/>
    <origin rpy="0 0 0" xyz="0 0 0.045"/>
    <axis xyz="0 0 1"/>
    <limit effort="38" velocity="1.571"/>
    <dynamics damping="0.5" friction="0.5"/>
  </joint>
  <link name="leg_4_shoulder1_shoulder2/INPUT_INTERFACE">
    <visual>
      <origin rpy="1.57079632679 0 1.57079632679" xyz="0 0 0.005"/>
      <geometry>
        <mesh filename="package://hebi_description/meshes/PM-2149-01.stl" scale="0.001 0.001 0.001"/>
      </geometry>
      <material name="black">
        <color rgba="0.1 0.1 0.1 1"/>
      </material>
    </visual>
    <visual>
      <origin rpy="1.57079632679 0 3.14159265359" xyz="0 -.03 .04"/>
      <geometry>
        <mesh filename="package://hebi_description/meshes/PM-2150-01L.stl" scale="0.001 0.001 0.001"/>
      </geometry>
      <material name="black">
        <color rgba="0.1 0.1 0.1 1"/>
      </material>
    </visual>
    <collision>
      <origin rpy="1.57079632679 0 1.57079632679" xyz="0 0 0.005"/>
      <geometry>
        <mesh filename="package://hebi_description/meshes/PM-2149-01.stl" scale="0.001 0.001 0.001"/>
      </geometry>
    </collision>
    <collision>
      <origin rpy="1.57079632679 0 3.14159265359" xyz="0 -.03 .04"/>
      <geometry>
        <mesh filename="package://hebi_description/meshes/PM-2150-01L.stl" scale="0.001 0.001 0.001"/>
      </geometry>
    </collision>
    <!-- NOTE: inertia is just modelled as small sphere, and could be improved. -->
    <inertial>
      <origin rpy="0 0 0" xyz="0 -0.01125 .0275"/>
      <mass value="0.215"/>
      <inertia ixx="0.0003096" ixy="0.0" ixz="0.0" iyy="0.0003096" iyz="0.0" izz="0.0003096"/>
    </inertial>
  </link>
  <gazebo reference="leg_4_shoulder1_shoulder2/INPUT_INTERFACE">
    <material>Gazebo/Black</material>
  </gazebo>
  <joint name="leg_4_shoulder1_shoulder2/OUTPUT_INTERFACE" type="fixed">
    <parent link="leg_4_shoulder1_shoulder2/INPUT_INTERFACE"/>
    <child link="Cricket/L4_J2_shoulder2/INPUT_INTERFACE"/>
    <origin rpy="-1.57079632679 0 0" xyz="0 -.0225 .055"/>
  </joint>
  <gazebo reference="leg_4_shoulder1_shoulder2/OUTPUT_INTERFACE">
    <disableFixedJointLumping>true</disableFixedJointLumping>
    <preserveFixedJoint>true</preserveFixedJoint>
  </gazebo>
  <link name="Cricket/L4_J2_shoulder2/INPUT_INTERFACE">
    <visual>
      <origin rpy="0 0 0" xyz="0 0 0"/>
      <geometry>
        <mesh filename="package://hebi_description/meshes/X8.stl" scale="0.001 0.001 0.001"/>
      </geometry>
      <material name="red">
        <color rgba=".82 0.06 0.06 1"/>
      </material>
    </visual>
    <collision>
      <origin rpy="0 0 0" xyz="0 0 0"/>
      <geometry>
        <mesh filename="package://hebi_description/meshes/X8.stl" scale="0.001 0.001 0.001"/>
      </geometry>
    </collision>
    <inertial>
      <mass value="0.5"/>
      <origin rpy="0 0 0" xyz="-0.0145 -0.0031 0.0242"/>
      <inertia ixx="0.000246" ixy="0.0000444" ixz="0.0000266" iyy="0.000380" iyz="0.00000422" izz="0.000463"/>
    </inertial>
  </link>
  <gazebo reference="Cricket/L4_J2_shoulder2/INPUT_INTERFACE">
    <material>Gazebo/Red</material>
  </gazebo>
  <link name="HEBI_SIM/Cricket/L4_J2_shoulder2/X8_16">
    <visual>
      <origin rpy="0 0 0" xyz="-0.03 0 0.02"/>
      <geometry>
        <sphere radius="0.001"/>
      </geometry>
    </visual>
    <inertial>
      <mass value="0.001"/>
      <origin rpy="0 0 0" xyz="0 0 0"/>
      <inertia ixx="0.000001" ixy="0" ixz="0" iyy="0.000001" iyz="0" izz="0.000001"/>
    </inertial>
  </link>
  <joint name="HEBI_SIM_JOINT/Cricket/L4_J2_shoulder2" type="fixed">
    <parent link="Cricket/L4_J2_shoulder2/INPUT_INTERFACE"/>
    <child link="HEBI_SIM/Cricket/L4_J2_shoulder2/X8_16"/>
    <origin rpy="0 0 0" xyz="0 0 0"/>
  </joint>
  <gazebo reference="HEBI_SIM_JOINT/Cricket/L4_J2_shoulder2">
    <disableFixedJointLumping>true</disableFixedJointLumping>
    <preserveFixedJoint>true</preserveFixedJoint>
  </gazebo>
  <joint name="Cricket/L4_J2_shoulder2" type="continuous">
    <parent link="Cricket/L4_J2_shoulder2/INPUT_INTERFACE"/>
    <child link="leg_4_knee_to_link_spacer/INPUT_INTERFACE"/>
    <origin rpy="0 0 0" xyz="0 0 0.045"/>
    <axis xyz="0 0 1"/>
    <limit effort="38" velocity="1.571"/>
    <dynamics damping="0.5" friction="0.5"/>
  </joint>
  <link name="leg_4_knee_to_link_spacer/INPUT_INTERFACE">
    <visual>
      <origin rpy="0 0 0" xyz="0.0 0.0 0.01"/>
      <geometry>
        <box size="0.05 0.05 0.02"/>
      </geometry>
      <material name="beige">
        <color rgba="0.96 0.945 0.871 1"/>
      </material>
    </visual>
    <inertial>
      <mass value="0.05"/>
      <origin rpy="0 0 0" xyz="0 0 0"/>
      <inertia ixx="0.001" ixy="0" ixz="0" iyy="0.001" iyz="0" izz="0.001"/>
    </inertial>
  </link>
  <joint name="leg_4_knee_to_link_spacer_child_joint" type="fixed">
    <origin rpy="0 0 0" xyz="0.0 0.0 0.02"/>
    <parent link="leg_4_knee_to_link_spacer/INPUT_INTERFACE"/>
    <child link="leg_4_shoulder2_knee/INPUT_INTERFACE"/>
  </joint>
  <link name="leg_4_shoulder2_knee/INPUT_INTERFACE">
    <!-- Input Cap -->
    <visual>
      <origin rpy="0 0 0" xyz="0 0 0"/>
      <geometry>
        <mesh filename="package://hebi_description/meshes/A-2038-02.stl"/>
      </geometry>
      <material name="black">
        <color rgba="0.1 0.1 0.1 1"/>
      </material>
    </visual>
    <collision>
      <origin rpy="0 0 0" xyz="0 0 0"/>
      <geometry>
        <mesh filename="package://hebi_description/meshes/A-2038-02.stl"/>
      </geometry>
    </collision>
    <!-- Link Pipe -->
    <visual>
      <origin rpy="0 1.57075 0" xyz="0.075 0 0.02"/>
      <geometry>
        <cylinder length="0.1246" radius=".016"/>
      </geometry>
      <material name="black">
        <color rgba="0.1 0.1 0.1 1"/>
      </material>
    </visual>
    <collision>
      <origin rpy="0 1.57075 0" xyz="0.075 0 0.02"/>
      <geometry>
        <cylinder length="0.1246" radius=".016"/>
      </geometry>
    </collision>
    <!-- Output Cap -->
    <visual>
      <origin rpy="0 0 0" xyz="0.15 0.0 0.04"/>
      <geometry>
        <mesh filename="package://hebi_description/meshes/A-2039-02.stl"/>
      </geometry>
      <material name="black">
        <color rgba="0.1 0.1 0.1 1"/>
      </material>
    </visual>
    <collision>
      <origin rpy="0 0 0" xyz="0.15 0.0 0.04"/>
      <geometry>
        <mesh filename="package://hebi_description/meshes/A-2039-02.stl"/>
      </geometry>
    </collision>
    <!-- Approximate inertia as thin rod about x axis -->
    <inertial>
      <origin rpy="0 0 0" xyz="0.075 0 0.02"/>
      <mass value="0.332"/>
      <inertia ixx="0.0" ixy="0.0" ixz="0.0" iyy="0.0006225" iyz="0.0" izz="0.0006225"/>
    </inertial>
  </link>
  <gazebo reference="leg_4_shoulder2_knee/INPUT_INTERFACE">
    <material>Gazebo/Black</material>
  </gazebo>
  <joint name="leg_4_shoulder2_knee/OUTPUT_JOINT" type="fixed">
    <parent link="leg_4_shoulder2_knee/INPUT_INTERFACE"/>
    <child link="Cricket/L4_J3_knee/INPUT_INTERFACE"/>
    <origin rpy="0 0 0" xyz="0.15 -0.0 0.04"/>
  </joint>
  <gazebo reference="leg_4_shoulder2_knee/OUTPUT_JOINT">
    <disableFixedJointLumping>true</disableFixedJointLumping>
    <preserveFixedJoint>true</preserveFixedJoint>
  </gazebo>
  <link name="Cricket/L4_J3_knee/INPUT_INTERFACE">
    <visual>
      <origin rpy="0 0 0" xyz="0 0 0"/>
      <geometry>
        <mesh filename="package://hebi_description/meshes/X8.stl" scale="0.001 0.001 0.001"/>
      </geometry>
      <material name="red">
        <color rgba=".82 0.06 0.06 1"/>
      </material>
    </visual>
    <collision>
      <origin rpy="0 0 0" xyz="0 0 0"/>
      <geometry>
        <mesh filename="package://hebi_description/meshes/X8.stl" scale="0.001 0.001 0.001"/>
      </geometry>
    </collision>
    <inertial>
      <mass value="0.5"/>
      <origin rpy="0 0 0" xyz="-0.0145 -0.0031 0.0242"/>
      <inertia ixx="0.000246" ixy="0.0000444" ixz="0.0000266" iyy="0.000380" iyz="0.00000422" izz="0.000463"/>
    </inertial>
  </link>
  <gazebo reference="Cricket/L4_J3_knee/INPUT_INTERFACE">
    <material>Gazebo/Red</material>
  </gazebo>
  <link name="HEBI_SIM/Cricket/L4_J3_knee/X8_16">
    <visual>
      <origin rpy="0 0 0" xyz="-0.03 0 0.02"/>
      <geometry>
        <sphere radius="0.001"/>
      </geometry>
    </visual>
    <inertial>
      <mass value="0.001"/>
      <origin rpy="0 0 0" xyz="0 0 0"/>
      <inertia ixx="0.000001" ixy="0" ixz="0" iyy="0.000001" iyz="0" izz="0.000001"/>
    </inertial>
  </link>
  <joint name="HEBI_SIM_JOINT/Cricket/L4_J3_knee" type="fixed">
    <parent link="Cricket/L4_J3_knee/INPUT_INTERFACE"/>
    <child link="HEBI_SIM/Cricket/L4_J3_knee/X8_16"/>
    <origin rpy="0 0 0" xyz="0 0 0"/>
  </joint>
  <gazebo reference="HEBI_SIM_JOINT/Cricket/L4_J3_knee">
    <disableFixedJointLumping>true</disableFixedJointLumping>
    <preserveFixedJoint>true</preserveFixedJoint>
  </gazebo>
  <joint name="Cricket/L4_J3_knee" type="continuous">
    <parent link="Cricket/L4_J3_knee/INPUT_INTERFACE"/>
    <child link="leg4_knee_ankle/INPUT_INTERFACE"/>
    <origin rpy="0 0 0" xyz="0 0 0.045"/>
    <axis xyz="0 0 1"/>
    <limit effort="38" velocity="1.571"/>
    <dynamics damping="0.5" friction="0.5"/>
  </joint>
  <link name="leg4_knee_ankle/INPUT_INTERFACE">
    <!-- Input Cap -->
    <visual>
      <origin rpy="0 0 0" xyz="0 0 0"/>
      <geometry>
        <mesh filename="package://hebi_description/meshes/A-2038-02.stl"/>
      </geometry>
      <material name="black">
        <color rgba="0.1 0.1 0.1 1"/>
      </material>
    </visual>
    <collision>
      <origin rpy="0 0 0" xyz="0 0 0"/>
      <geometry>
        <mesh filename="package://hebi_description/meshes/A-2038-02.stl"/>
      </geometry>
    </collision>
    <!-- Link Pipe -->
    <visual>
      <origin rpy="0 1.57075 0" xyz="0.1375 0 0.02"/>
      <geometry>
        <cylinder length="0.2496" radius=".016"/>
      </geometry>
      <material name="black">
        <color rgba="0.1 0.1 0.1 1"/>
      </material>
    </visual>
    <collision>
      <origin rpy="0 1.57075 0" xyz="0.1375 0 0.02"/>
      <geometry>
        <cylinder length="0.2496" radius=".016"/>
      </geometry>
    </collision>
    <!-- Output Cap -->
    <visual>
      <origin rpy="0 0 0" xyz="0.275 0.0 0.04"/>
      <geometry>
        <mesh filename="package://hebi_description/meshes/A-2039-02.stl"/>
      </geometry>
      <material name="black">
        <color rgba="0.1 0.1 0.1 1"/>
      </material>
    </visual>
    <collision>
      <origin rpy="0 0 0" xyz="0.275 0.0 0.04"/>
      <geometry>
        <mesh filename="package://hebi_description/meshes/A-2039-02.stl"/>
      </geometry>
    </collision>
    <!-- Approximate inertia as thin rod about x axis -->
    <inertial>
      <origin rpy="0 0 0" xyz="0.1375 0 0.02"/>
      <mass value="0.382"/>
      <inertia ixx="0.0" ixy="0.0" ixz="0.0" iyy="0.00240739583333" iyz="0.0" izz="0.00240739583333"/>
    </inertial>
  </link>
  <gazebo reference="leg4_knee_ankle/INPUT_INTERFACE">
    <material>Gazebo/Black</material>
  </gazebo>
  <joint name="leg4_knee_ankle/OUTPUT_JOINT" type="fixed">
    <parent link="leg4_knee_ankle/INPUT_INTERFACE"/>
    <child link="leg4_ankle_spacer/INPUT_INTERFACE"/>
    <origin rpy="0 0 0" xyz="0.275 -0.0 0.04"/>
  </joint>
  <gazebo reference="leg4_knee_ankle/OUTPUT_JOINT">
    <disableFixedJointLumping>true</disableFixedJointLumping>
    <preserveFixedJoint>true</preserveFixedJoint>
  </gazebo>
  <link name="leg4_ankle_spacer/INPUT_INTERFACE">
    <inertial>
      <mass value="0.01"/>
      <origin rpy="0 0 0" xyz="0 0 0"/>
      <inertia ixx="0.001" ixy="0" ixz="0" iyy="0.001" iyz="0" izz="0.001"/>
    </inertial>
  </link>
  <link name="Cricket/L4_J4_ankle/INPUT_INTERFACE">
    <visual>
      <origin rpy="0 0 0" xyz="0 0 0"/>
      <geometry>
        <mesh filename="package://hebi_description/meshes/X8.stl" scale="0.001 0.001 0.001"/>
      </geometry>
      <material name="red">
        <color rgba=".82 0.06 0.06 1"/>
      </material>
    </visual>
    <collision>
      <origin rpy="0 0 0" xyz="0 0 0"/>
      <geometry>
        <mesh filename="package://hebi_description/meshes/X8.stl" scale="0.001 0.001 0.001"/>
      </geometry>
    </collision>
    <inertial>
      <mass value="0.5"/>
      <origin rpy="0 0 0" xyz="-0.0145 -0.0031 0.0242"/>
      <inertia ixx="0.000246" ixy="0.0000444" ixz="0.0000266" iyy="0.000380" iyz="0.00000422" izz="0.000463"/>
    </inertial>
  </link>
  <gazebo reference="Cricket/L4_J4_ankle/INPUT_INTERFACE">
    <material>Gazebo/Red</material>
  </gazebo>
  <link name="HEBI_SIM/Cricket/L4_J4_ankle/X8_16">
    <visual>
      <origin rpy="0 0 0" xyz="-0.03 0 0.02"/>
      <geometry>
        <sphere radius="0.001"/>
      </geometry>
    </visual>
    <inertial>
      <mass value="0.001"/>
      <origin rpy="0 0 0" xyz="0 0 0"/>
      <inertia ixx="0.000001" ixy="0" ixz="0" iyy="0.000001" iyz="0" izz="0.000001"/>
    </inertial>
  </link>
  <joint name="HEBI_SIM_JOINT/Cricket/L4_J4_ankle" type="fixed">
    <parent link="Cricket/L4_J4_ankle/INPUT_INTERFACE"/>
    <child link="HEBI_SIM/Cricket/L4_J4_ankle/X8_16"/>
    <origin rpy="0 0 0" xyz="0 0 0"/>
  </joint>
  <gazebo reference="HEBI_SIM_JOINT/Cricket/L4_J4_ankle">
    <disableFixedJointLumping>true</disableFixedJointLumping>
    <preserveFixedJoint>true</preserveFixedJoint>
  </gazebo>
  <joint name="Cricket/L4_J4_ankle" type="continuous">
    <parent link="leg4_ankle_spacer/INPUT_INTERFACE"/>
    <child link="Cricket/L4_J4_ankle/INPUT_INTERFACE"/>
    <origin rpy="0 3.14159265359 0" xyz="0 0 0.045"/>
    <axis xyz="0 0 1"/>
    <limit effort="38" velocity="1.571"/>
    <dynamics damping="0.5" friction="0.5"/>
  </joint>
  <joint name="Cricket/L4_J4_ankle_fixed" type="fixed">
    <parent link="Cricket/L4_J4_ankle/INPUT_INTERFACE"/>
    <child link="leg4_track_bracket_1/INPUT_INTERFACE"/>
    <origin rpy="0 0 0" xyz="0 0 0"/>
  </joint>
  <link name="leg4_track_bracket_1/INPUT_INTERFACE">
    <visual>
      <origin rpy="0 0 0" xyz="-0.0685 0.0 -0.005"/>
      <geometry>
        <box size="0.15 0.05 0.01"/>
      </geometry>
      <material name="beige">
        <color rgba="0.96 0.945 0.871 1"/>
      </material>
    </visual>
    <inertial>
      <mass value="0.3"/>
      <origin rpy="0 0 0" xyz="0 0 0"/>
      <inertia ixx="0.001" ixy="0" ixz="0" iyy="0.001" iyz="0" izz="0.001"/>
    </inertial>
  </link>
  <joint name="leg4_track_bracket_1_child_joint" type="fixed">
    <origin rpy="0 0 0" xyz="-0.137 0.0 -0.01"/>
    <parent link="leg4_track_bracket_1/INPUT_INTERFACE"/>
    <child link="leg4_track_bracket_2/INPUT_INTERFACE"/>
  </joint>
  <link name="leg4_track_bracket_2/INPUT_INTERFACE">
    <visual>
      <origin rpy="0 0 0" xyz="0.0 0.0 0.025"/>
      <geometry>
        <box size="0.08 0.05 0.05"/>
      </geometry>
      <material name="beige">
        <color rgba="0.96 0.945 0.871 1"/>
      </material>
    </visual>
    <inertial>
      <mass value="0.3"/>
      <origin rpy="0 0 0" xyz="0 0 0"/>
      <inertia ixx="0.001" ixy="0" ixz="0" iyy="0.001" iyz="0" izz="0.001"/>
    </inertial>
  </link>
  <joint name="leg4_track_bracket_2_child_joint" type="fixed">
    <origin rpy="0 0 0" xyz="0.0 0.0 0.05"/>
    <parent link="leg4_track_bracket_2/INPUT_INTERFACE"/>
    <child link="leg4_track_bracket_3/INPUT_INTERFACE"/>
  </joint>
  <link name="leg4_track_bracket_3/INPUT_INTERFACE">
    <visual>
      <origin rpy="0 0 0" xyz="-0.0685 0.0 -0.005"/>
      <geometry>
        <box size="0.15 0.05 0.01"/>
      </geometry>
      <material name="beige">
        <color rgba="0.96 0.945 0.871 1"/>
      </material>
    </visual>
    <inertial>
      <mass value="0.3"/>
      <origin rpy="0 0 0" xyz="0 0 0"/>
      <inertia ixx="0.001" ixy="0" ixz="0" iyy="0.001" iyz="0" izz="0.001"/>
    </inertial>
  </link>
  <joint name="leg4_track_bracket_3_child_joint" type="fixed">
    <origin rpy="0 3.14159265359 0" xyz="-0.137 0.0 -0.01"/>
    <parent link="leg4_track_bracket_3/INPUT_INTERFACE"/>
    <child link="Cricket/L4_J5_track/INPUT_INTERFACE"/>
  </joint>
  <link name="Cricket/L4_J5_track/INPUT_INTERFACE">
    <visual>
      <origin rpy="0 0 0" xyz="0 0 0"/>
      <geometry>
        <mesh filename="package://hebi_description/meshes/X8.stl" scale="0.001 0.001 0.001"/>
      </geometry>
      <material name="red">
        <color rgba=".82 0.06 0.06 1"/>
      </material>
    </visual>
    <collision>
      <origin rpy="0 0 0" xyz="0 0 0"/>
      <geometry>
        <mesh filename="package://hebi_description/meshes/X8.stl" scale="0.001 0.001 0.001"/>
      </geometry>
    </collision>
    <inertial>
      <mass value="0.5"/>
      <origin rpy="0 0 0" xyz="-0.0145 -0.0031 0.0242"/>
      <inertia ixx="0.000246" ixy="0.0000444" ixz="0.0000266" iyy="0.000380" iyz="0.00000422" izz="0.000463"/>
    </inertial>
  </link>
  <gazebo reference="Cricket/L4_J5_track/INPUT_INTERFACE">
    <material>Gazebo/Red</material>
  </gazebo>
  <link name="HEBI_SIM/Cricket/L4_J5_track/X8_16">
    <visual>
      <origin rpy="0 0 0" xyz="-0.03 0 0.02"/>
      <geometry>
        <sphere radius="0.001"/>
      </geometry>
    </visual>
    <inertial>
      <mass value="0.001"/>
      <origin rpy="0 0 0" xyz="0 0 0"/>
      <inertia ixx="0.000001" ixy="0" ixz="0" iyy="0.000001" iyz="0" izz="0.000001"/>
    </inertial>
  </link>
  <joint name="HEBI_SIM_JOINT/Cricket/L4_J5_track" type="fixed">
    <parent link="Cricket/L4_J5_track/INPUT_INTERFACE"/>
    <child link="HEBI_SIM/Cricket/L4_J5_track/X8_16"/>
    <origin rpy="0 0 0" xyz="0 0 0"/>
  </joint>
  <gazebo reference="HEBI_SIM_JOINT/Cricket/L4_J5_track">
    <disableFixedJointLumping>true</disableFixedJointLumping>
    <preserveFixedJoint>true</preserveFixedJoint>
  </gazebo>
  <joint name="Cricket/L4_J5_track" type="continuous">
    <parent link="Cricket/L4_J5_track/INPUT_INTERFACE"/>
    <child link="leg4_drive_pulley/INPUT_INTERFACE"/>
    <origin rpy="0 0 0" xyz="0 0 0.045"/>
    <axis xyz="0 0 1"/>
    <limit effort="38" velocity="1.571"/>
    <dynamics damping="0.5" friction="0.5"/>
  </joint>
  <link name="leg4_drive_pulley/INPUT_INTERFACE">
    <visual>
      <origin rpy="0 0 0" xyz="0 0 0.020"/>
      <geometry>
        <cylinder length="0.033" radius="0.068"/>
      </geometry>
      <material name="black">
        <color rgba="0.1 0.1 0.1 1"/>
      </material>
    </visual>
    <collision>
      <origin rpy="0 0 0" xyz="0 0 0.020"/>
      <geometry>
        <cylinder length="0.033" radius="0.068"/>
      </geometry>
    </collision>
    <inertial>
      <mass value="0.1"/>
      <origin rpy="0 0 0" xyz="0 0 0"/>
      <inertia ixx="0.001" ixy="0" ixz="0" iyy="0.001" iyz="0" izz="0.001"/>
    </inertial>
  </link>
  <link name="leg4_idle_pulley">
    <visual>
      <origin rpy="0 0 0" xyz="0.0 0.0 -0.03"/>
      <geometry>
        <cylinder length="0.033" radius="0.068"/>
      </geometry>
      <material name="black">
        <color rgba="0.1 0.1 0.1 1"/>
      </material>
    </visual>
    <inertial>
      <mass value="0.1"/>
      <origin rpy="0 0 0" xyz="0 0 0"/>
      <inertia ixx="0.001" ixy="0" ixz="0" iyy="0.001" iyz="0" izz="0.001"/>
    </inertial>
  </link>
  <joint name="leg4_idle_pulley_joint" type="continuous">
    <origin rpy="0 0 0" xyz="0 0 0"/>
    <parent link="Cricket/L4_J4_ankle/INPUT_INTERFACE"/>
    <child link="leg4_idle_pulley"/>
    <axis xyz="0 0 1"/>
  </joint>
</robot>

